Workbook

Sheet 39-6-OZ
B2: STOCK CARD- REF.NO | U2: YRAR | V2: 2023
B3: THE EMPIRE JUTE MILL | R3: HESSIAN
B4: DESCRIPTION OF GOODS:- HESSIAN CLOTH 39-6 OZ/40 8X7 | R4: SACKING
A5: NATURE OF PACKING :- 1/B 2000 YDS | R5: YARN
D6: OPENING BALANCE | G6: RECEIPT | I6: TOTAL | K6: ISSUES | M6: GROSS WT | O6: CLOSING BALLACE | Q6: REMARKS | R6: NET WGT. PER BALE | S6: 331.695
D7: NO.OF | E7: WEIGHT IN | G7: NO.OF | H7: WEIGHT IN | I7: NO.OF | J7: WEIGHT IN | K7: NO.OF | L7: NET WT | O7: NO.OF | P7: WEIGHT IN | R7: P.SHEET WGT | S7: 2.488
B8: DATE | D8: BALE | E8: KGS | G8: BALE | I8: BALE | J8: KGS | K8: BALE | L8: KGS | N8: PACK SHEET | O8: BALE | P8: KGS | R8: TOTAL WGT | S8: =S6+S7 -> 334.183
B9: 1 | D9: 43 | E9: =$S$8*D9/1000 -> 14.369869 | G9: 16 | H9: =G9*S$8/1000 -> 5.346928 | I9: =D9+G9 -> 59 | J9: =$S$8*I9/1000 -> 19.716797 | L9: =K9*S$6/1000 -> 0 | M9: =K9*S$8/1000 -> 0 | N9: =K9*S$7/1000 -> 0 | O9: =I9-K9 -> 59 | P9: =$S$8*O9/1000 -> 19.716797
B10: 2 | D10: =+O9 -> 59 | E10: =$S$8*D10/1000 -> 19.716797 | G10: 7 | H10: =G10*S$8/1000 -> 2.339281 | I10: =D10+G10 -> 66 | J10: =$S$8*I10/1000 -> 22.056078 | L10: =K10*S$6/1000 -> 0 | M10: =K10*S$8/1000 -> 0 | N10: =K10*S$7/1000 -> 0 | O10: =I10-K10 -> 66 | P10: =$S$8*O10/1000 -> 22.056078
B11: 3 | D11: =+O10 -> 66 | E11: =$S$8*D11/1000 -> 22.056078 | G11: 7 | H11: =G11*S$8/1000 -> 2.339281 | I11: =D11+G11 -> 73 | J11: =$S$8*I11/1000 -> 24.395359 | L11: =K11*S$6/1000 -> 0 | M11: =K11*S$8/1000 -> 0 | N11: =K11*S$7/1000 -> 0 | O11: =I11-K11 -> 73 | P11: =$S$8*O11/1000 -> 24.395359
B12: 4 | D12: =+O11 -> 73 | E12: =$S$8*D12/1000 -> 24.395359 | G12: 9 | H12: =G12*S$8/1000 -> 3.007647 | I12: =D12+G12 -> 82 | J12: =$S$8*I12/1000 -> 27.403006 | L12: =K12*S$6/1000 -> 0 | M12: =K12*S$8/1000 -> 0 | N12: =K12*S$7/1000 -> 0 | O12: =I12-K12 -> 82 | P12: =$S$8*O12/1000 -> 27.403006
B13: 5 | D13: =+O12 -> 82 | E13: =$S$8*D13/1000 -> 27.403006 | G13: 16 | H13: =G13*S$8/1000 -> 5.346928 | I13: =D13+G13 -> 98 | J13: =$S$8*I13/1000 -> 32.749934 | K13: 3 | L13: =K13*S$6/1000 -> 0.995085 | M13: =K13*S$8/1000 -> 1.002549 | N13: =K13*S$7/1000 -> 0.007464 | O13: =I13-K13 -> 95 | P13: =$S$8*O13/1000 -> 31.747385
B14: 6 | D14: =+O13 -> 95 | E14: =$S$8*D14/1000 -> 31.747385 | G14: 6 | H14: =G14*S$8/1000 -> 2.005098 | I14: =D14+G14 -> 101 | J14: =$S$8*I14/1000 -> 33.752483 | L14: =K14*S$6/1000 -> 0 | M14: =K14*S$8/1000 -> 0 | N14: =K14*S$7/1000 -> 0 | O14: =I14-K14 -> 101 | P14: =$S$8*O14/1000 -> 33.752483
B15: 7 | D15: =+O14 -> 101 | E15: =$S$8*D15/1000 -> 33.752483 | G15: 0 | H15: =G15*S$8/1000 -> 0 | I15: =D15+G15 -> 101 | J15: =$S$8*I15/1000 -> 33.752483 | L15: =K15*S$6/1000 -> 0 | M15: =K15*S$8/1000 -> 0 | N15: =K15*S$7/1000 -> 0 | O15: =I15-K15 -> 101 | P15: =$S$8*O15/1000 -> 33.752483
B16: 8 | D16: =+O15 -> 101 | E16: =$S$8*D16/1000 -> 33.752483 | G16: 0 | H16: =G16*S$8/1000 -> 0 | I16: =D16+G16 -> 101 | J16: =$S$8*I16/1000 -> 33.752483 | L16: =K16*S$6/1000 -> 0 | M16: =K16*S$8/1000 -> 0 | N16: =K16*S$7/1000 -> 0 | O16: =I16-K16 -> 101 | P16: =$S$8*O16/1000 -> 33.752483
B17: 9 | D17: =+O16 -> 101 | E17: =$S$8*D17/1000 -> 33.752483 | G17: 8 | H17: =G17*S$8/1000 -> 2.673464 | I17: =D17+G17 -> 109 | J17: =$S$8*I17/1000 -> 36.425947 | L17: =K17*S$6/1000 -> 0 | M17: =K17*S$8/1000 -> 0 | N17: =K17*S$7/1000 -> 0 | O17: =I17-K17 -> 109 | P17: =$S$8*O17/1000 -> 36.425947
B18: 10 | D18: =+O17 -> 109 | E18: =$S$8*D18/1000 -> 36.425947 | H18: =G18*S$8/1000 -> 0 | I18: =D18+G18 -> 109 | J18: =$S$8*I18/1000 -> 36.425947 | L18: =K18*S$6/1000 -> 0 | M18: =K18*S$8/1000 -> 0 | N18: =K18*S$7/1000 -> 0 | O18: =I18-K18 -> 109 | P18: =$S$8*O18/1000 -> 36.425947
B19: 11 | D19: =+O18 -> 109 | E19: =$S$8*D19/1000 -> 36.425947 | H19: =G19*S$8/1000 -> 0 | I19: =D19+G19 -> 109 | J19: =$S$8*I19/1000 -> 36.425947 | L19: =K19*S$6/1000 -> 0 | M19: =K19*S$8/1000 -> 0 | N19: =K19*S$7/1000 -> 0 | O19: =I19-K19 -> 109 | P19: =$S$8*O19/1000 -> 36.425947
B20: 12 | D20: =+O19 -> 109 | E20: =$S$8*D20/1000 -> 36.425947 | G20: 1 | H20: =G20*S$8/1000 -> 0.334183 | I20: =D20+G20 -> 110 | J20: =$S$8*I20/1000 -> 36.76013 | L20: =K20*S$6/1000 -> 0 | M20: =K20*S$8/1000 -> 0 | N20: =K20*S$7/1000 -> 0 | O20: =I20-K20 -> 110 | P20: =$S$8*O20/1000 -> 36.76013
B21: 13 | D21: =+O20 -> 110 | E21: =$S$8*D21/1000 -> 36.76013 | H21: =G21*S$8/1000 -> 0 | I21: =D21+G21 -> 110 | J21: =$S$8*I21/1000 -> 36.76013 | L21: =K21*S$6/1000 -> 0 | M21: =K21*S$8/1000 -> 0 | N21: =K21*S$7/1000 -> 0 | O21: =I21-K21 -> 110 | P21: =$S$8*O21/1000 -> 36.76013
B22: 14 | D22: =+O21 -> 110 | E22: =$S$8*D22/1000 -> 36.76013 | H22: =G22*S$8/1000 -> 0 | I22: =D22+G22 -> 110 | J22: =$S$8*I22/1000 -> 36.76013 | L22: =K22*S$6/1000 -> 0 | M22: =K22*S$8/1000 -> 0 | N22: =K22*S$7/1000 -> 0 | O22: =I22-K22 -> 110 | P22: =$S$8*O22/1000 -> 36.76013 | S22: 1000
B23: 15 | D23: =+O22 -> 110 | E23: =$S$8*D23/1000 -> 36.76013 | H23: =G23*S$8/1000 -> 0 | I23: =D23+G23 -> 110 | J23: =$S$8*I23/1000 -> 36.76013 | L23: =K23*S$6/1000 -> 0 | M23: =K23*S$8/1000 -> 0 | N23: =K23*S$7/1000 -> 0 | O23: =I23-K23 -> 110 | P23: =$S$8*O23/1000 -> 36.76013
B24: 16 | D24: =+O23 -> 110 | E24: =$S$8*D24/1000 -> 36.76013 | G24: 2 | H24: =G24*S$8/1000 -> 0.668366 | I24: =D24+G24 -> 112 | J24: =$S$8*I24/1000 -> 37.428496 | K24: 112 | L24: =K24*S$6/1000 -> 37.14984 | M24: =K24*S$8/1000 -> 37.428496 | N24: =K24*S$7/1000 -> 0.278656 | O24: =I24-K24 -> 0 | P24: =$S$8*O24/1000 -> 0 | R24: 7.5 | S24: 39 | U24: 6 | V24: 40 | X24: 28.35 | Y24: 2000
B25: 17 | D25: =+O24 -> 0 | E25: =$S$8*D25/1000 -> 0 | H25: =G25*S$8/1000 -> 0 | I25: =D25+G25 -> 0 | J25: =$S$8*I25/1000 -> 0 | L25: =K25*S$6/1000 -> 0 | M25: =K25*S$8/1000 -> 0 | N25: =K25*S$7/1000 -> 0 | O25: =I25-K25 -> 0 | P25: =$S$8*O25/1000 -> 0 | S25: =S24*U24/V24*X24*Y24/S22 -> 331.695
B26: 18 | D26: =+O25 -> 0 | E26: =$S$8*D26/1000 -> 0 | H26: =G26*S$8/1000 -> 0 | I26: =D26+G26 -> 0 | J26: =$S$8*I26/1000 -> 0 | L26: =K26*S$6/1000 -> 0 | M26: =K26*S$8/1000 -> 0 | N26: =K26*S$7/1000 -> 0 | O26: =I26-K26 -> 0 | P26: =$S$8*O26/1000 -> 0 | S26: =S25*R24/S22 -> 2.4877125
B27: 19 | D27: =+O26 -> 0 | E27: =$S$8*D27/1000 -> 0 | H27: =G27*S$8/1000 -> 0 | I27: =D27+G27 -> 0 | J27: =$S$8*I27/1000 -> 0 | L27: =K27*S$6/1000 -> 0 | M27: =K27*S$8/1000 -> 0 | N27: =K27*S$7/1000 -> 0 | O27: =I27-K27 -> 0 | P27: =$S$8*O27/1000 -> 0 | S27: =S25+S26 -> 334.18271
B28: 20 | D28: =+O27 -> 0 | E28: =$S$8*D28/1000 -> 0 | H28: =G28*S$8/1000 -> 0 | I28: =D28+G28 -> 0 | J28: =$S$8*I28/1000 -> 0 | L28: =K28*S$6/1000 -> 0 | M28: =K28*S$8/1000 -> 0 | N28: =K28*S$7/1000 -> 0 | O28: =I28-K28 -> 0 | P28: =$S$8*O28/1000 -> 0
B29: 21 | D29: =+O28 -> 0 | E29: =$S$8*D29/1000 -> 0 | H29: =G29*S$8/1000 -> 0 | I29: =D29+G29 -> 0 | J29: =$S$8*I29/1000 -> 0 | L29: =K29*S$6/1000 -> 0 | M29: =K29*S$8/1000 -> 0 | N29: =K29*S$7/1000 -> 0 | O29: =I29-K29 -> 0 | P29: =$S$8*O29/1000 -> 0
B30: 22 | D30: =+O29 -> 0 | E30: =$S$8*D30/1000 -> 0 | G30: 0 | H30: =G30*S$8/1000 -> 0 | I30: =D30+G30 -> 0 | J30: =$S$8*I30/1000 -> 0 | L30: =K30*S$6/1000 -> 0 | M30: =K30*S$8/1000 -> 0 | N30: =K30*S$7/1000 -> 0 | O30: =I30-K30 -> 0 | P30: =$S$8*O30/1000 -> 0
B31: 23 | D31: =+O30 -> 0 | E31: =$S$8*D31/1000 -> 0 | G31: 1 | H31: =G31*S$8/1000 -> 0.334183 | I31: =D31+G31 -> 1 | J31: =$S$8*I31/1000 -> 0.334183 | L31: =K31*S$6/1000 -> 0 | M31: =K31*S$8/1000 -> 0 | N31: =K31*S$7/1000 -> 0 | O31: =I31-K31 -> 1 | P31: =$S$8*O31/1000 -> 0.334183
B32: 24 | D32: =+O31 -> 1 | E32: =$S$8*D32/1000 -> 0.334183 | G32: 1 | H32: =G32*S$8/1000 -> 0.334183 | I32: =D32+G32 -> 2 | J32: =$S$8*I32/1000 -> 0.668366 | L32: =K32*S$6/1000 -> 0 | M32: =K32*S$8/1000 -> 0 | N32: =K32*S$7/1000 -> 0 | O32: =I32-K32 -> 2 | P32: =$S$8*O32/1000 -> 0.668366
B33: 25 | D33: =+O32 -> 2 | E33: =$S$8*D33/1000 -> 0.668366 | H33: =G33*S$8/1000 -> 0 | I33: =D33+G33 -> 2 | J33: =$S$8*I33/1000 -> 0.668366 | L33: =K33*S$6/1000 -> 0 | M33: =K33*S$8/1000 -> 0 | N33: =K33*S$7/1000 -> 0 | O33: =I33-K33 -> 2 | P33: =$S$8*O33/1000 -> 0.668366
B34: 26 | D34: =+O33 -> 2 | E34: =$S$8*D34/1000 -> 0.668366 | G34: 1 | H34: =G34*S$8/1000 -> 0.334183 | I34: =D34+G34 -> 3 | J34: =$S$8*I34/1000 -> 1.002549 | L34: =K34*S$6/1000 -> 0 | M34: =K34*S$8/1000 -> 0 | N34: =K34*S$7/1000 -> 0 | O34: =I34-K34 -> 3 | P34: =$S$8*O34/1000 -> 1.002549
B35: 27 | D35: =+O34 -> 3 | E35: =$S$8*D35/1000 -> 1.002549 | G35: 3 | H35: =G35*S$8/1000 -> 1.002549 | I35: =D35+G35 -> 6 | J35: =$S$8*I35/1000 -> 2.005098 | L35: =K35*S$6/1000 -> 0 | M35: =K35*S$8/1000 -> 0 | N35: =K35*S$7/1000 -> 0 | O35: =I35-K35 -> 6 | P35: =$S$8*O35/1000 -> 2.005098
B36: 28 | D36: =+O35 -> 6 | E36: =$S$8*D36/1000 -> 2.005098 | H36: =G36*S$8/1000 -> 0 | I36: =D36+G36 -> 6 | J36: =$S$8*I36/1000 -> 2.005098 | L36: =K36*S$6/1000 -> 0 | M36: =K36*S$8/1000 -> 0 | N36: =K36*S$7/1000 -> 0 | O36: =I36-K36 -> 6 | P36: =$S$8*O36/1000 -> 2.005098
B37: 29 | D37: =+O36 -> 6 | E37: =$S$8*D37/1000 -> 2.005098 | G37: 4 | H37: =G37*S$8/1000 -> 1.336732 | I37: =D37+G37 -> 10 | J37: =$S$8*I37/1000 -> 3.34183 | L37: =K37*S$6/1000 -> 0 | M37: =K37*S$8/1000 -> 0 | N37: =K37*S$7/1000 -> 0 | O37: =I37-K37 -> 10 | P37: =$S$8*O37/1000 -> 3.34183
B38: 30 | D38: =+O37 -> 10 | E38: =$S$8*D38/1000 -> 3.34183 | G38: 6 | H38: =G38*S$8/1000 -> 2.005098 | I38: =D38+G38 -> 16 | J38: =$S$8*I38/1000 -> 5.346928 | L38: =K38*S$6/1000 -> 0 | M38: =K38*S$8/1000 -> 0 | N38: =K38*S$7/1000 -> 0 | O38: =I38-K38 -> 16 | P38: =$S$8*O38/1000 -> 5.346928
B39: 31 | D39: =+O38 -> 16 | E39: =$S$8*D39/1000 -> 5.346928 | G39: 1 | H39: =G39*S$8/1000 -> 0.334183 | I39: =D39+G39 -> 17 | J39: =$S$8*I39/1000 -> 5.681111 | L39: =K39*S$6/1000 -> 0 | M39: =K39*S$8/1000 -> 0 | N39: =K39*S$7/1000 -> 0 | O39: =I39-K39 -> 17 | P39: =$S$8*O39/1000 -> 5.681111
B40: TOTAL | G40: =SUM(G9:G39) -> 89 | H40: =SUM(H9:H39) -> 29.742287 | K40: =SUM(K9:K39) -> 115 | L40: =SUM(L9:L39) -> 38.144925 | M40: =SUM(M9:M39) -> 38.431045 | N40: =SUM(N9:N39) -> 0.28612
B42: PROD PACK SHEET | G42: =G40*S7/1000 -> 0.221432 | H42: =+G40*S6/1000 -> 29.520855 | J42: DESPATCH PACK SHEET | L42: =+K40*S7/1000 -> 0.28612
...

Sheet 20 X10 
B2: STOCK CARD- REF.NO
B3: THE EMPIRE JUTE MILL | R3: HESSIAN
B4: DESCRIPTION OF GOODS:- HESSIAN CLOTH 20X10 72 GM/BAG | R4: SACKING
A5: NATURE OF PACKING :- 1/B 2000 PCS | R5: YARN
B6: DATE | D6: OPENING BALANCE | G6: RECEIPT | I6: TOTAL | K6: ISSUES | M6: GROSS WT | O6: CLOSING BALLACE | Q6: REMARKS | R6: NET WGT. PER BALE | S6: 144
D7: NO.OF | E7: WEIGHT IN | G7: NO.OF | H7: WEIGHT IN | I7: NO.OF | J7: WEIGHT IN | K7: NO.OF | L7: NET WT | O7: NO.OF | P7: WEIGHT IN | R7: P.SHEET WGT | S7: =S6*0.75% -> 1.08
D8: BALE | E8: KGS | G8: BALE | H8: KGS | I8: BALE | J8: KGS | K8: BALE | L8: KGS | N8: PACK SHEET | O8: BALE | P8: KGS | R8: TOTAL WGT | S8: =S6+S7 -> 145.08
B9: 1 | E9: =$S$8*D9/1000 -> 0 | H9: =$S$8*G9/1000 -> 0 | I9: =D9+G9 -> 0 | J9: =$S$8*I9/1000 -> 0 | L9: =K9*S$6/1000 -> 0 | M9: =K9*S$8/1000 -> 0 | N9: =K9*S$7/1000 -> 0 | O9: =I9-K9 -> 0 | P9: =$S$8*O9/1000 -> 0 | Q9: =P9*T8/1000 -> 0
B10: 2 | D10: =+O9 -> 0 | E10: =$S$8*D10/1000 -> 0 | H10: =$S$8*G10/1000 -> 0 | I10: =D10+G10 -> 0 | J10: =$S$8*I10/1000 -> 0 | L10: =K10*S$6/1000 -> 0 | M10: =K10*S$8/1000 -> 0 | N10: =K10*S$7/1000 -> 0 | O10: =I10-K10 -> 0 | P10: =$S$8*O10/1000 -> 0
B11: 3 | D11: =+O10 -> 0 | E11: =$S$8*D11/1000 -> 0 | H11: =$S$8*G11/1000 -> 0 | I11: =D11+G11 -> 0 | J11: =$S$8*I11/1000 -> 0 | L11: =K11*S$6/1000 -> 0 | M11: =K11*S$8/1000 -> 0 | N11: =K11*S$7/1000 -> 0 | O11: =I11-K11 -> 0 | P11: =$S$8*O11/1000 -> 0
B12: 4 | D12: =+O11 -> 0 | E12: =$S$8*D12/1000 -> 0 | H12: =$S$8*G12/1000 -> 0 | I12: =D12+G12 -> 0 | J12: =$S$8*I12/1000 -> 0 | L12: =K12*S$6/1000 -> 0 | M12: =K12*S$8/1000 -> 0 | N12: =K12*S$7/1000 -> 0 | O12: =I12-K12 -> 0 | P12: =$S$8*O12/1000 -> 0
B13: 5 | D13: =+O12 -> 0 | E13: =$S$8*D13/1000 -> 0 | H13: =$S$8*G13/1000 -> 0 | I13: =D13+G13 -> 0 | J13: =$S$8*I13/1000 -> 0 | L13: =K13*S$6/1000 -> 0 | M13: =K13*S$8/1000 -> 0 | N13: =K13*S$7/1000 -> 0 | O13: =I13-K13 -> 0 | P13: =$S$8*O13/1000 -> 0
B14: 6 | D14: =+O13 -> 0 | E14: =$S$8*D14/1000 -> 0 | H14: =$S$8*G14/1000 -> 0 | I14: =D14+G14 -> 0 | J14: =$S$8*I14/1000 -> 0 | L14: =K14*S$6/1000 -> 0 | M14: =K14*S$8/1000 -> 0 | N14: =K14*S$7/1000 -> 0 | O14: =I14-K14 -> 0 | P14: =$S$8*O14/1000 -> 0
B15: 7 | D15: =+O14 -> 0 | E15: =$S$8*D15/1000 -> 0 | H15: =$S$8*G15/1000 -> 0 | I15: =D15+G15 -> 0 | J15: =$S$8*I15/1000 -> 0 | L15: =K15*S$6/1000 -> 0 | M15: =K15*S$8/1000 -> 0 | N15: =K15*S$7/1000 -> 0 | O15: =I15-K15 -> 0 | P15: =$S$8*O15/1000 -> 0
B16: 8 | D16: =+O15 -> 0 | E16: =$S$8*D16/1000 -> 0 | H16: =$S$8*G16/1000 -> 0 | I16: =D16+G16 -> 0 | J16: =$S$8*I16/1000 -> 0 | L16: =K16*S$6/1000 -> 0 | M16: =K16*S$8/1000 -> 0 | N16: =K16*S$7/1000 -> 0 | O16: =I16-K16 -> 0 | P16: =$S$8*O16/1000 -> 0
B17: 9 | D17: =+O16 -> 0 | E17: =$S$8*D17/1000 -> 0 | H17: =$S$8*G17/1000 -> 0 | I17: =D17+G17 -> 0 | J17: =$S$8*I17/1000 -> 0 | L17: =K17*S$6/1000 -> 0 | M17: =K17*S$8/1000 -> 0 | N17: =K17*S$7/1000 -> 0 | O17: =I17-K17 -> 0 | P17: =$S$8*O17/1000 -> 0
B18: 10 | D18: =+O17 -> 0 | E18: =$S$8*D18/1000 -> 0 | H18: =$S$8*G18/1000 -> 0 | I18: =D18+G18 -> 0 | J18: =$S$8*I18/1000 -> 0 | L18: =K18*S$6/1000 -> 0 | M18: =K18*S$8/1000 -> 0 | N18: =K18*S$7/1000 -> 0 | O18: =I18-K18 -> 0 | P18: =$S$8*O18/1000 -> 0
B19: 11 | D19: =+O18 -> 0 | E19: =$S$8*D19/1000 -> 0 | H19: =$S$8*G19/1000 -> 0 | I19: =D19+G19 -> 0 | J19: =$S$8*I19/1000 -> 0 | L19: =K19*S$6/1000 -> 0 | M19: =K19*S$8/1000 -> 0 | N19: =K19*S$7/1000 -> 0 | O19: =I19-K19 -> 0 | P19: =$S$8*O19/1000 -> 0
B20: 12 | D20: =+O19 -> 0 | E20: =$S$8*D20/1000 -> 0 | H20: =$S$8*G20/1000 -> 0 | I20: =D20+G20 -> 0 | J20: =$S$8*I20/1000 -> 0 | L20: =K20*S$6/1000 -> 0 | M20: =K20*S$8/1000 -> 0 | N20: =K20*S$7/1000 -> 0 | O20: =I20-K20 -> 0 | P20: =$S$8*O20/1000 -> 0
B21: 13 | D21: =+O20 -> 0 | E21: =$S$8*D21/1000 -> 0 | H21: =$S$8*G21/1000 -> 0 | I21: =D21+G21 -> 0 | J21: =$S$8*I21/1000 -> 0 | L21: =K21*S$6/1000 -> 0 | M21: =K21*S$8/1000 -> 0 | N21: =K21*S$7/1000 -> 0 | O21: =I21-K21 -> 0 | P21: =$S$8*O21/1000 -> 0
... B38: 30 | D38: =+O37 -> 0 | E38: =$S$8*D38/1000 -> 0 | H38: =$S$8*G38/1000 -> 0 | I38: =D38+G38 -> 0 | J38: =$S$8*I38/1000 -> 0 | L38: =K38*S$6/1000 -> 0 | M38: =K38*S$8/1000 -> 0 | N38: =K38*S$7/1000 -> 0 | O38: =I38-K38 -> 0 | P38: =$S$8*O38/1000 -> 0
B39: 31 | E39: =$S$8*D39/1000 -> 0 | H39: =$S$8*G39/1000 -> 0 | I39: =D39+G39 -> 0 | J39: =$S$8*I39/1000 -> 0 | L39: =K39*S$6/1000 -> 0 | M39: =K39*S$8/1000 -> 0 | N39: =K39*S$7/1000 -> 0 | O39: =I39-K39 -> 0 | P39: =$S$8*O39/1000 -> 0
B40: TOTAL | F40: =SUM(F9:F39) -> 0 | G40: =SUM(G9:G39) -> 0 | H40: =SUM(H9:H39) -> 0 | K40: =SUM(K9:K39) -> 0 | L40: =SUM(L9:L39) -> 0 | M40: =SUM(M9:M39) -> 0 | N40: =SUM(N9:N39) -> 0 | R40: 72 | S40: 2000 | U40: =R40*S40/1000 -> 144 | V40: 144
S41: 0.75 | U41: =U40*S41/1000 -> 0.108 | V41: 0.5
B42: PACK SHEET | G42: =G40*S7/1000 -> 0 | J42: DESPATCH PACKSHEET | L42: =+K40*S7/1000 -> 0 | U42: TOTAL | V42: =V40+V41 -> 144.5

Sheet 38-8.12-OZ 
B2: STOCK CARD- REF.NO
B3: THE EMPIRE JUTE MILL | R3: HESSIAN
B4: DESCRIPTION OF GOODS:- HESSIAN CLOTH 38-8.12 OZ/40 , 11X10 PLAIN | R4: SACKING
A5: NATURE OF PACKING :- 1/B 2000 YDS | R5: YARN
B6: DATE | D6: OPENING BALANCE | G6: RECEIPT | I6: TOTAL | K6: ISSUES | M6: GROSS WT | O6: CLOSING BALLACE | Q6: REMARKS | R6: NET WGT. PER BALE | S6: 437.384
D7: NO.OF | E7: WEIGHT IN | G7: NO.OF | H7: WEIGHT IN M.T | I7: NO.OF | J7: WEIGHT IN | K7: NO.OF | L7: NET WT | O7: NO.OF | P7: WEIGHT IN | R7: P.SHEET WGT | S7: 3.28
D8: BALE | E8: KGS | G8: BALE | I8: BALE | J8: KGS | K8: BALE | L8: KGS | N8: PACK SHEET | O8: BALE | P8: KGS | R8: TOTAL WGT | S8: =S6+S7 -> 440.664
B9: 1 | D9: 40 | E9: =$S$8*D9/1000 -> 17.62656 | H9: =$S$8*G9/1000 -> 0 | I9: =D9+G9 -> 40 | J9: =$S$8*I9/1000 -> 17.62656 | K9: 40 | L9: =K9*S$6/1000 -> 17.49536 | M9: =K9*S$8/1000 -> 17.62656 | N9: =K9*S$7/1000 -> 0.1312 | O9: =I9-K9 -> 0 | P9: =$S$8*O9/1000 -> 0 | Q9: =P9*T8/1000 -> 0
B10: 2 | D10: =+O9 -> 0 | E10: =$S$8*D10/1000 -> 0 | G10: 3 | H10: =$S$8*G10/1000 -> 1.321992 | I10: =D10+G10 -> 3 | J10: =$S$8*I10/1000 -> 1.321992 | L10: =K10*S$6/1000 -> 0 | M10: =K10*S$8/1000 -> 0 | N10: =K10*S$7/1000 -> 0 | O10: =I10-K10 -> 3 | P10: =$S$8*O10/1000 -> 1.321992
B11: 3 | D11: =+O10 -> 3 | E11: =$S$8*D11/1000 -> 1.321992 | G11: 3 | H11: =$S$8*G11/1000 -> 1.321992 | I11: =D11+G11 -> 6 | J11: =$S$8*I11/1000 -> 2.643984 | L11: =K11*S$6/1000 -> 0 | M11: =K11*S$8/1000 -> 0 | N11: =K11*S$7/1000 -> 0 | O11: =I11-K11 -> 6 | P11: =$S$8*O11/1000 -> 2.643984
B12: 4 | D12: =+O11 -> 6 | E12: =$S$8*D12/1000 -> 2.643984 | G12: 3 | H12: =$S$8*G12/1000 -> 1.321992 | I12: =D12+G12 -> 9 | J12: =$S$8*I12/1000 -> 3.965976 | L12: =K12*S$6/1000 -> 0 | M12: =K12*S$8/1000 -> 0 | N12: =K12*S$7/1000 -> 0 | O12: =I12-K12 -> 9 | P12: =$S$8*O12/1000 -> 3.965976
B13: 5 | D13: =+O12 -> 9 | E13: =$S$8*D13/1000 -> 3.965976 | G13: 8 | H13: =$S$8*G13/1000 -> 3.525312 | I13: =D13+G13 -> 17 | J13: =$S$8*I13/1000 -> 7.491288 | K13: 12 | L13: =K13*S$6/1000 -> 5.248608 | M13: =K13*S$8/1000 -> 5.287968 | N13: =K13*S$7/1000 -> 0.03936 | O13: =I13-K13 -> 5 | P13: =$S$8*O13/1000 -> 2.20332
B14: 6 | D14: =+O13 -> 5 | E14: =$S$8*D14/1000 -> 2.20332 | G14: 6 | H14: =$S$8*G14/1000 -> 2.643984 | I14: =D14+G14 -> 11 | J14: =$S$8*I14/1000 -> 4.847304 | L14: =K14*S$6/1000 -> 0 | M14: =K14*S$8/1000 -> 0 | N14: =K14*S$7/1000 -> 0 | O14: =I14-K14 -> 11 | P14: =$S$8*O14/1000 -> 4.847304
B15: 7 | D15: =+O14 -> 11 | E15: =$S$8*D15/1000 -> 4.847304 | G15: 4 | H15: =$S$8*G15/1000 -> 1.762656 | I15: =D15+G15 -> 15 | J15: =$S$8*I15/1000 -> 6.60996 | L15: =K15*S$6/1000 -> 0 | M15: =K15*S$8/1000 -> 0 | N15: =K15*S$7/1000 -> 0 | O15: =I15-K15 -> 15 | P15: =$S$8*O15/1000 -> 6.60996
B16: 8 | D16: =+O15 -> 15 | E16: =$S$8*D16/1000 -> 6.60996 | G16: 0 | H16: =$S$8*G16/1000 -> 0 | I16: =D16+G16 -> 15 | J16: =$S$8*I16/1000 -> 6.60996 | L16: =K16*S$6/1000 -> 0 | M16: =K16*S$8/1000 -> 0 | N16: =K16*S$7/1000 -> 0 | O16: =I16-K16 -> 15 | P16: =$S$8*O16/1000 -> 6.60996
B17: 9 | D17: =+O16 -> 15 | E17: =$S$8*D17/1000 -> 6.60996 | G17: 7 | H17: =$S$8*G17/1000 -> 3.084648 | I17: =D17+G17 -> 22 | J17: =$S$8*I17/1000 -> 9.694608 | K17: 22 | L17: =K17*S$6/1000 -> 9.622448 | M17: =K17*S$8/1000 -> 9.694608 | N17: =K17*S$7/1000 -> 0.07216 | O17: =I17-K17 -> 0 | P17: =$S$8*O17/1000 -> 0
B18: 10 | D18: =+O17 -> 0 | E18: =$S$8*D18/1000 -> 0 | H18: =$S$8*G18/1000 -> 0 | I18: =D18+G18 -> 0 | J18: =$S$8*I18/1000 -> 0 | L18: =K18*S$6/1000 -> 0 | M18: =K18*S$8/1000 -> 0 | N18: =K18*S$7/1000 -> 0 | O18: =I18-K18 -> 0 | P18: =$S$8*O18/1000 -> 0
B19: 11 | D19: =+O18 -> 0 | E19: =$S$8*D19/1000 -> 0 | H19: =$S$8*G19/1000 -> 0 | I19: =D19+G19 -> 0 | J19: =$S$8*I19/1000 -> 0 | L19: =K19*S$6/1000 -> 0 | M19: =K19*S$8/1000 -> 0 | N19: =K19*S$7/1000 -> 0 | O19: =I19-K19 -> 0 | P19: =$S$8*O19/1000 -> 0
B20: 12 | D20: =+O19 -> 0 | E20: =$S$8*D20/1000 -> 0 | G20: 2 | H20: =$S$8*G20/1000 -> 0.881328 | I20: =D20+G20 -> 2 | J20: =$S$8*I20/1000 -> 0.881328 | L20: =K20*S$6/1000 -> 0 | M20: =K20*S$8/1000 -> 0 | N20: =K20*S$7/1000 -> 0 | O20: =I20-K20 -> 2 | P20: =$S$8*O20/1000 -> 0.881328
B21: 13 | D21: =+O20 -> 2 | E21: =$S$8*D21/1000 -> 0.881328 | H21: =$S$8*G21/1000 -> 0 | I21: =D21+G21 -> 2 | J21: =$S$8*I21/1000 -> 0.881328 | L21: =K21*S$6/1000 -> 0 | M21: =K21*S$8/1000 -> 0 | N21: =K21*S$7/1000 -> 0 | O21: =I21-K21 -> 2 | P21: =$S$8*O21/1000 -> 0.881328
B22: 14 | D22: =+O21 -> 2 | E22: =$S$8*D22/1000 -> 0.881328 | H22: =$S$8*G22/1000 -> 0 | I22: =D22+G22 -> 2 | J22: =$S$8*I22/1000 -> 0.881328 | L22: =K22*S$6/1000 -> 0 | M22: =K22*S$8/1000 -> 0 | N22: =K22*S$7/1000 -> 0 | O22: =I22-K22 -> 2 | P22: =$S$8*O22/1000 -> 0.881328
B23: 15 | D23: =+O22 -> 2 | E23: =$S$8*D23/1000 -> 0.881328 | H23: =$S$8*G23/1000 -> 0 | I23: =D23+G23 -> 2 | J23: =$S$8*I23/1000 -> 0.881328 | L23: =K23*S$6/1000 -> 0 | M23: =K23*S$8/1000 -> 0 | N23: =K23*S$7/1000 -> 0 | O23: =I23-K23 -> 2 | P23: =$S$8*O23/1000 -> 0.881328
B24: 16 | D24: =+O23 -> 2 | E24: =$S$8*D24/1000 -> 0.881328 | G24: 7 | H24: =$S$8*G24/1000 -> 3.084648 | I24: =D24+G24 -> 9 | J24: =$S$8*I24/1000 -> 3.965976 | K24: 5 | L24: =K24*S$6/1000 -> 2.18692 | M24: =K24*S$8/1000 -> 2.20332 | N24: =K24*S$7/1000 -> 0.0164 | O24: =I24-K24 -> 4 | P24: =$S$8*O24/1000 -> 1.762656
B25: 17 | D25: =+O24 -> 4 | E25: =$S$8*D25/1000 -> 1.762656 | H25: =$S$8*G25/1000 -> 0 | I25: =D25+G25 -> 4 | J25: =$S$8*I25/1000 -> 1.762656 | L25: =K25*S$6/1000 -> 0 | M25: =K25*S$8/1000 -> 0 | N25: =K25*S$7/1000 -> 0 | O25: =I25-K25 -> 4 | P25: =$S$8*O25/1000 -> 1.762656
B26: 18 | D26: =+O25 -> 4 | E26: =$S$8*D26/1000 -> 1.762656 | H26: =$S$8*G26/1000 -> 0 | I26: =D26+G26 -> 4 | J26: =$S$8*I26/1000 -> 1.762656 | L26: =K26*S$6/1000 -> 0 | M26: =K26*S$8/1000 -> 0 | N26: =K26*S$7/1000 -> 0 | O26: =I26-K26 -> 4 | P26: =$S$8*O26/1000 -> 1.762656
B27: 19 | D27: =+O26 -> 4 | E27: =$S$8*D27/1000 -> 1.762656 | H27: =$S$8*G27/1000 -> 0 | I27: =D27+G27 -> 4 | J27: =$S$8*I27/1000 -> 1.762656 | L27: =K27*S$6/1000 -> 0 | M27: =K27*S$8/1000 -> 0 | N27: =K27*S$7/1000 -> 0 | O27: =I27-K27 -> 4 | P27: =$S$8*O27/1000 -> 1.762656
B28: 20 | D28: =+O27 -> 4 | E28: =$S$8*D28/1000 -> 1.762656 | H28: =$S$8*G28/1000 -> 0 | I28: =D28+G28 -> 4 | J28: =$S$8*I28/1000 -> 1.762656 | L28: =K28*S$6/1000 -> 0 | M28: =K28*S$8/1000 -> 0 | N28: =K28*S$7/1000 -> 0 | O28: =I28-K28 -> 4 | P28: =$S$8*O28/1000 -> 1.762656
B29: 21 | D29: =+O28 -> 4 | E29: =$S$8*D29/1000 -> 1.762656 | H29: =$S$8*G29/1000 -> 0 | I29: =D29+G29 -> 4 | J29: =$S$8*I29/1000 -> 1.762656 | L29: =K29*S$6/1000 -> 0 | M29: =K29*S$8/1000 -> 0 | N29: =K29*S$7/1000 -> 0 | O29: =I29-K29 -> 4 | P29: =$S$8*O29/1000 -> 1.762656
B30: 22 | D30: =+O29 -> 4 | E30: =$S$8*D30/1000 -> 1.762656 | G30: 0 | H30: =$S$8*G30/1000 -> 0 | I30: =D30+G30 -> 4 | J30: =$S$8*I30/1000 -> 1.762656 | L30: =K30*S$6/1000 -> 0 | M30: =K30*S$8/1000 -> 0 | N30: =K30*S$7/1000 -> 0 | O30: =I30-K30 -> 4 | P30: =$S$8*O30/1000 -> 1.762656
B31: 23 | D31: =+O30 -> 4 | E31: =$S$8*D31/1000 -> 1.762656 | G31: 8 | H31: =$S$8*G31/1000 -> 3.525312 | I31: =D31+G31 -> 12 | J31: =$S$8*I31/1000 -> 5.287968 | L31: =K31*S$6/1000 -> 0 | M31: =K31*S$8/1000 -> 0 | N31: =K31*S$7/1000 -> 0 | O31: =I31-K31 -> 12 | P31: =$S$8*O31/1000 -> 5.287968
B32: 24 | D32: =+O31 -> 12 | E32: =$S$8*D32/1000 -> 5.287968 | G32: 5 | H32: =$S$8*G32/1000 -> 2.20332 | I32: =D32+G32 -> 17 | J32: =$S$8*I32/1000 -> 7.491288 | L32: =K32*S$6/1000 -> 0 | M32: =K32*S$8/1000 -> 0 | N32: =K32*S$7/1000 -> 0 | O32: =I32-K32 -> 17 | P32: =$S$8*O32/1000 -> 7.491288
B33: 25 | D33: =+O32 -> 17 | E33: =$S$8*D33/1000 -> 7.491288 | H33: =$S$8*G33/1000 -> 0 | I33: =D33+G33 -> 17 | J33: =$S$8*I33/1000 -> 7.491288 | L33: =K33*S$6/1000 -> 0 | M33: =K33*S$8/1000 -> 0 | N33: =K33*S$7/1000 -> 0 | O33: =I33-K33 -> 17 | P33: =$S$8*O33/1000 -> 7.491288
B34: 26 | D34: =+O33 -> 17 | E34: =$S$8*D34/1000 -> 7.491288 | G34: 3 | H34: =$S$8*G34/1000 -> 1.321992 | I34: =D34+G34 -> 20 | J34: =$S$8*I34/1000 -> 8.81328 | L34: =K34*S$6/1000 -> 0 | M34: =K34*S$8/1000 -> 0 | N34: =K34*S$7/1000 -> 0 | O34: =I34-K34 -> 20 | P34: =$S$8*O34/1000 -> 8.81328
B35: 27 | D35: =+O34 -> 20 | E35: =$S$8*D35/1000 -> 8.81328 | G35: 6 | H35: =$S$8*G35/1000 -> 2.643984 | I35: =D35+G35 -> 26 | J35: =$S$8*I35/1000 -> 11.457264 | K35: 22 | L35: =K35*S$6/1000 -> 9.622448 | M35: =K35*S$8/1000 -> 9.694608 | N35: =K35*S$7/1000 -> 0.07216 | O35: =I35-K35 -> 4 | P35: =$S$8*O35/1000 -> 1.762656
B36: 28 | D36: =+O35 -> 4 | E36: =$S$8*D36/1000 -> 1.762656 | H36: =$S$8*G36/1000 -> 0 | I36: =D36+G36 -> 4 | J36: =$S$8*I36/1000 -> 1.762656 | L36: =K36*S$6/1000 -> 0 | M36: =K36*S$8/1000 -> 0 | N36: =K36*S$7/1000 -> 0 | O36: =I36-K36 -> 4 | P36: =$S$8*O36/1000 -> 1.762656
B37: 29 | D37: =+O36 -> 4 | E37: =$S$8*D37/1000 -> 1.762656 | G37: 2 | H37: =$S$8*G37/1000 -> 0.881328 | I37: =D37+G37 -> 6 | J37: =$S$8*I37/1000 -> 2.643984 | L37: =K37*S$6/1000 -> 0 | M37: =K37*S$8/1000 -> 0 | N37: =K37*S$7/1000 -> 0 | O37: =I37-K37 -> 6 | P37: =$S$8*O37/1000 -> 2.643984
B38: 30 | D38: =+O37 -> 6 | E38: =$S$8*D38/1000 -> 2.643984 | G38: 9 | H38: =$S$8*G38/1000 -> 3.965976 | I38: =D38+G38 -> 15 | J38: =$S$8*I38/1000 -> 6.60996 | L38: =K38*S$6/1000 -> 0 | M38: =K38*S$8/1000 -> 0 | N38: =K38*S$7/1000 -> 0 | O38: =I38-K38 -> 15 | P38: =$S$8*O38/1000 -> 6.60996
B39: 31 | D39: =+O38 -> 15 | E39: =$S$8*D39/1000 -> 6.60996 | G39: 3 | H39: =$S$8*G39/1000 -> 1.321992 | I39: =D39+G39 -> 18 | J39: =$S$8*I39/1000 -> 7.931952 | L39: =K39*S$6/1000 -> 0 | M39: =K39*S$8/1000 -> 0 | N39: =K39*S$7/1000 -> 0 | O39: =I39-K39 -> 18 | P39: =$S$8*O39/1000 -> 7.931952
B40: TOTAL | F40: =SUM(F9:F39) -> 0 | G40: =SUM(G9:G39) -> 79 | H40: =SUM(H9:H39) -> 34.812456 | K40: =SUM(K9:K39) -> 101 | L40: =SUM(L9:L39) -> 44.175784 | M40: =SUM(M9:M39) -> 44.507064 | N40: =SUM(N9:N39) -> 0.33128 | R40: 38 | S40: 8.12 | U40: 40 | V40: 28.35 | W40: 200 | X40: 2000
U41: =R40*S40/U40*V40*X40/1000 -> 437.3838
...

Sheet 44-8.12 OZ (2)
B2: STOCK CARD- REF.NO
B3: THE EMPIRE JUTE MILL | R3: HESSIAN
B4: HESSIAN CLOTH 44-8.12 OZ/40 | R4: SACKING
A5: NATURE OF PACKING :- 1/B 1500 YDS | R5: YARN
B6: DATE | D6: OPENING BALANCE | G6: RECEIPT | I6: TOTAL | K6: ISSUES | M6: GROSS WT | O6: CLOSING BALLACE | Q6: REMARKS | R6: NET WGT. PER BALE | S6: =44*8.12/40*28.35*1500/1000 -> 379.8333
D7: NO.OF | E7: WEIGHT IN | G7: NO.OF | H7: WEIGHT IN | I7: NO.OF | J7: WEIGHT IN | K7: NO.OF | L7: NET WT | O7: NO.OF | P7: WEIGHT IN | R7: P.SHEET WGT | S7: =S6*0.75% -> 2.8487498
D8: BALE | E8: KGS | G8: BALE | H8: KGS | I8: BALE | J8: KGS | K8: BALE | L8: KGS | N8: PACK SHEET | O8: BALE | P8: KGS | R8: TOTAL WGT | S8: =S6+S7 -> 382.68205
B9: 1 | E9: =$S$8*D9/1000 -> 0 | H9: =$S$8*G9/1000 -> 0 | I9: =D9+G9 -> 0 | J9: =$S$8*I9/1000 -> 0 | L9: =K9*S$6/1000 -> 0 | M9: =K9*S$8/1000 -> 0 | N9: =K9*S$7/1000 -> 0 | O9: =I9-K9 -> 0 | P9: =$S$8*O9/1000 -> 0
B10: 2 | D10: =+O9 -> 0 | E10: =$S$8*D10/1000 -> 0 | H10: =$S$8*G10/1000 -> 0 | I10: =D10+G10 -> 0 | J10: =$S$8*I10/1000 -> 0 | L10: =K10*S$6/1000 -> 0 | M10: =K10*S$8/1000 -> 0 | N10: =K10*S$7/1000 -> 0 | O10: =I10-K10 -> 0 | P10: =$S$8*O10/1000 -> 0
B11: 3 | D11: =+O10 -> 0 | E11: =$S$8*D11/1000 -> 0 | H11: =$S$8*G11/1000 -> 0 | I11: =D11+G11 -> 0 | J11: =$S$8*I11/1000 -> 0 | L11: =K11*S$6/1000 -> 0 | M11: =K11*S$8/1000 -> 0 | N11: =K11*S$7/1000 -> 0 | O11: =I11-K11 -> 0 | P11: =$S$8*O11/1000 -> 0
B12: 4 | D12: =+O11 -> 0 | E12: =$S$8*D12/1000 -> 0 | H12: =$S$8*G12/1000 -> 0 | I12: =D12+G12 -> 0 | J12: =$S$8*I12/1000 -> 0 | L12: =K12*S$6/1000 -> 0 | M12: =K12*S$8/1000 -> 0 | N12: =K12*S$7/1000 -> 0 | O12: =I12-K12 -> 0 | P12: =$S$8*O12/1000 -> 0
B13: 5 | D13: =+O12 -> 0 | E13: =$S$8*D13/1000 -> 0 | H13: =$S$8*G13/1000 -> 0 | I13: =D13+G13 -> 0 | J13: =$S$8*I13/1000 -> 0 | L13: =K13*S$6/1000 -> 0 | M13: =K13*S$8/1000 -> 0 | N13: =K13*S$7/1000 -> 0 | O13: =I13-K13 -> 0 | P13: =$S$8*O13/1000 -> 0
B14: 6 | D14: =+O13 -> 0 | E14: =$S$8*D14/1000 -> 0 | H14: =$S$8*G14/1000 -> 0 | I14: =D14+G14 -> 0 | J14: =$S$8*I14/1000 -> 0 | L14: =K14*S$6/1000 -> 0 | M14: =K14*S$8/1000 -> 0 | N14: =K14*S$7/1000 -> 0 | O14: =I14-K14 -> 0 | P14: =$S$8*O14/1000 -> 0
B15: 7 | D15: =+O14 -> 0 | E15: =$S$8*D15/1000 -> 0 | H15: =$S$8*G15/1000 -> 0 | I15: =D15+G15 -> 0 | J15: =$S$8*I15/1000 -> 0 | L15: =K15*S$6/1000 -> 0 | M15: =K15*S$8/1000 -> 0 | N15: =K15*S$7/1000 -> 0 | O15: =I15-K15 -> 0 | P15: =$S$8*O15/1000 -> 0
B16: 8 | D16: =+O15 -> 0 | E16: =$S$8*D16/1000 -> 0 | H16: =$S$8*G16/1000 -> 0 | I16: =D16+G16 -> 0 | J16: =$S$8*I16/1000 -> 0 | L16: =K16*S$6/1000 -> 0 | M16: =K16*S$8/1000 -> 0 | N16: =K16*S$7/1000 -> 0 | O16: =I16-K16 -> 0 | P16: =$S$8*O16/1000 -> 0
B17: 9 | D17: =+O16 -> 0 | E17: =$S$8*D17/1000 -> 0 | H17: =$S$8*G17/1000 -> 0 | I17: =D17+G17 -> 0 | J17: =$S$8*I17/1000 -> 0 | L17: =K17*S$6/1000 -> 0 | M17: =K17*S$8/1000 -> 0 | N17: =K17*S$7/1000 -> 0 | O17: =I17-K17 -> 0 | P17: =$S$8*O17/1000 -> 0
B18: 10 | D18: =+O17 -> 0 | E18: =$S$8*D18/1000 -> 0 | H18: =$S$8*G18/1000 -> 0 | I18: =D18+G18 -> 0 | J18: =$S$8*I18/1000 -> 0 | L18: =K18*S$6/1000 -> 0 | M18: =K18*S$8/1000 -> 0 | N18: =K18*S$7/1000 -> 0 | O18: =I18-K18 -> 0 | P18: =$S$8*O18/1000 -> 0
B19: 11 | D19: =+O18 -> 0 | E19: =$S$8*D19/1000 -> 0 | H19: =$S$8*G19/1000 -> 0 | I19: =D19+G19 -> 0 | J19: =$S$8*I19/1000 -> 0 | L19: =K19*S$6/1000 -> 0 | M19: =K19*S$8/1000 -> 0 | N19: =K19*S$7/1000 -> 0 | O19: =I19-K19 -> 0 | P19: =$S$8*O19/1000 -> 0
B20: 12 | D20: =+O19 -> 0 | E20: =$S$8*D20/1000 -> 0 | H20: =$S$8*G20/1000 -> 0 | I20: =D20+G20 -> 0 | J20: =$S$8*I20/1000 -> 0 | L20: =K20*S$6/1000 -> 0 | M20: =K20*S$8/1000 -> 0 | N20: =K20*S$7/1000 -> 0 | O20: =I20-K20 -> 0 | P20: =$S$8*O20/1000 -> 0
B21: 13 | D21: =+O20 -> 0 | E21: =$S$8*D21/1000 -> 0 | H21: =$S$8*G21/1000 -> 0 | I21: =D21+G21 -> 0 | J21: =$S$8*I21/1000 -> 0 | L21: =K21*S$6/1000 -> 0 | M21: =K21*S$8/1000 -> 0 | N21: =K21*S$7/1000 -> 0 | O21: =I21-K21 -> 0 | P21: =$S$8*O21/1000 -> 0
... B28: 20 | D28: =+O27 -> 0 | E28: =$S$8*D28/1000 -> 0 | H28: =$S$8*G28/1000 -> 0 | I28: =D28+G28 -> 0 | J28: =$S$8*I28/1000 -> 0 | L28: =K28*S$6/1000 -> 0 | M28: =K28*S$8/1000 -> 0 | N28: =K28*S$7/1000 -> 0 | O28: =I28-K28 -> 0 | P28: =$S$8*O28/1000 -> 0
B29: 21 | D29: =+O28 -> 0 | E29: =$S$8*D29/1000 -> 0 | H29: =$S$8*G29/1000 -> 0 | I29: =D29+G29 -> 0 | J29: 0.222 | L29: =K29*S$6/1000 -> 0 | M29: =K29*S$8/1000 -> 0 | N29: =K29*S$7/1000 -> 0 | O29: =I29-K29 -> 0 | P29: =$S$8*O29/1000 -> 0
B30: 22 | D30: =+O29 -> 0 | E30: =$S$8*D30/1000 -> 0 | H30: =$S$8*G30/1000 -> 0 | I30: =D30+G30 -> 0 | J30: =$S$8*I30/1000 -> 0 | L30: =K30*S$6/1000 -> 0 | M30: =K30*S$8/1000 -> 0 | N30: =K30*S$7/1000 -> 0 | O30: =I30-K30 -> 0 | P30: =$S$8*O30/1000 -> 0
B31: 23 | D31: =+O30 -> 0 | E31: =$S$8*D31/1000 -> 0 | H31: =$S$8*G31/1000 -> 0 | I31: =D31+G31 -> 0 | J31: =$S$8*I31/1000 -> 0 | L31: =K31*S$6/1000 -> 0 | M31: =K31*S$8/1000 -> 0 | N31: =K31*S$7/1000 -> 0 | O31: =I31-K31 -> 0 | P31: =$S$8*O31/1000 -> 0
B32: 24 | D32: =+O31 -> 0 | E32: =$S$8*D32/1000 -> 0 | H32: =$S$8*G32/1000 -> 0 | I32: =D32+G32 -> 0 | J32: =$S$8*I32/1000 -> 0 | L32: =K32*S$6/1000 -> 0 | M32: =K32*S$8/1000 -> 0 | N32: =K32*S$7/1000 -> 0 | O32: =I32-K32 -> 0 | P32: =$S$8*O32/1000 -> 0
B33: 25 | D33: =+O32 -> 0 | E33: =$S$8*D33/1000 -> 0 | H33: =$S$8*G33/1000 -> 0 | I33: =D33+G33 -> 0 | J33: =$S$8*I33/1000 -> 0 | L33: =K33*S$6/1000 -> 0 | M33: =K33*S$8/1000 -> 0 | N33: =K33*S$7/1000 -> 0 | O33: =I33-K33 -> 0 | P33: =$S$8*O33/1000 -> 0
B34: 26 | D34: =+O33 -> 0 | E34: =$S$8*D34/1000 -> 0 | H34: =$S$8*G34/1000 -> 0 | I34: =D34+G34 -> 0 | J34: =$S$8*I34/1000 -> 0 | L34: =K34*S$6/1000 -> 0 | M34: =K34*S$8/1000 -> 0 | N34: =K34*S$7/1000 -> 0 | O34: =I34-K34 -> 0 | P34: =$S$8*O34/1000 -> 0
B35: 27 | D35: =+O34 -> 0 | E35: =$S$8*D35/1000 -> 0 | H35: =$S$8*G35/1000 -> 0 | I35: =D35+G35 -> 0 | J35: =$S$8*I35/1000 -> 0 | L35: =K35*S$6/1000 -> 0 | M35: =K35*S$8/1000 -> 0 | N35: =K35*S$7/1000 -> 0 | O35: =I35-K35 -> 0 | P35: =$S$8*O35/1000 -> 0
B36: 28 | D36: =+O35 -> 0 | E36: =$S$8*D36/1000 -> 0 | H36: =$S$8*G36/1000 -> 0 | I36: =D36+G36 -> 0 | J36: =$S$8*I36/1000 -> 0 | L36: =K36*S$6/1000 -> 0 | M36: =K36*S$8/1000 -> 0 | N36: =K36*S$7/1000 -> 0 | O36: =I36-K36 -> 0 | P36: =$S$8*O36/1000 -> 0
B37: 29 | D37: =+O36 -> 0 | E37: =$S$8*D37/1000 -> 0 | H37: =$S$8*G37/1000 -> 0 | I37: =D37+G37 -> 0 | J37: =$S$8*I37/1000 -> 0 | L37: =K37*S$6/1000 -> 0 | M37: =K37*S$8/1000 -> 0 | N37: =K37*S$7/1000 -> 0 | O37: =I37-K37 -> 0 | P37: =$S$8*O37/1000 -> 0
B38: 30 | D38: =+O37 -> 0 | E38: =$S$8*D38/1000 -> 0 | H38: =$S$8*G38/1000 -> 0 | I38: =D38+G38 -> 0 | J38: =$S$8*I38/1000 -> 0 | L38: =K38*S$6/1000 -> 0 | M38: =K38*S$8/1000 -> 0 | N38: =K38*S$7/1000 -> 0 | O38: =I38-K38 -> 0 | P38: =$S$8*O38/1000 -> 0
B39: 31 | D39: =+O38 -> 0 | E39: =$S$8*D39/1000 -> 0 | H39: =$S$8*G39/1000 -> 0 | I39: =D39+G39 -> 0 | J39: =$S$8*I39/1000 -> 0 | L39: =K39*S$6/1000 -> 0 | M39: =K39*S$8/1000 -> 0 | N39: =K39*S$7/1000 -> 0 | O39: =I39-K39 -> 0 | P39: =$S$8*O39/1000 -> 0
B40: TOTAL | F40: =SUM(F9:F39) -> 0 | G40: =SUM(G9:G39) -> 0 | H40: =SUM(H9:H39) -> 0 | K40: =SUM(K9:K39) -> 0 | L40: =SUM(L9:L39) -> 0 | N40: =SUM(N9:N39) -> 0
B42: PACK SHEET | G42: =G40*S7/1000 -> 0 | H42: =+G40*S6/1000 -> 0 | J42: DESPATCH PACKSHEET | L42: =K40*S7/1000 -> 0

Sheet 44-8.12 OZ
B2: STOCK CARD- REF.NO
B3: THE EMPIRE JUTE MILL | R3: HESSIAN
B4: HESSIAN CLOTH 44-8.12 OZ | R4: SACKING
A5: NATURE OF PACKING :- 1/B 1000 YDS | R5: YARN
B6: DATE | D6: OPENING BALANCE | G6: RECEIPT | I6: TOTAL | K6: ISSUES | M6: GROSS WT | O6: CLOSING BALLACE | Q6: REMARKS | R6: NET WGT. PER BALE | S6: =44*8.12/40*28.35*1000/1000 -> 253.2222
D7: NO.OF | E7: WEIGHT IN | G7: NO.OF | H7: WEIGHT IN | I7: NO.OF | J7: WEIGHT IN | K7: NO.OF | L7: NET WT | O7: NO.OF | P7: WEIGHT IN | R7: P.SHEET WGT | S7: =S6*0.75% -> 1.8991665
D8: BALE | E8: KGS | G8: BALE | H8: KGS | I8: BALE | J8: KGS | K8: BALE | L8: KGS | N8: PACK SHEET | O8: BALE | P8: KGS | R8: TOTAL WGT | S8: =S6+S7 -> 255.12137
B9: 1 | E9: =$S$8*D9/1000 -> 0 | H9: =$S$8*G9/1000 -> 0 | I9: =D9+G9 -> 0 | J9: =$S$8*I9/1000 -> 0 | L9: =K9*S$6/1000 -> 0 | M9: =K9*S$8/1000 -> 0 | N9: =K9*S$7/1000 -> 0 | O9: =I9-K9 -> 0 | P9: =$S$8*O9/1000 -> 0
B10: 2 | D10: =+O9 -> 0 | E10: =$S$8*D10/1000 -> 0 | H10: =$S$8*G10/1000 -> 0 | I10: =D10+G10 -> 0 | J10: =$S$8*I10/1000 -> 0 | L10: =K10*S$6/1000 -> 0 | M10: =K10*S$8/1000 -> 0 | N10: =K10*S$7/1000 -> 0 | O10: =I10-K10 -> 0 | P10: =$S$8*O10/1000 -> 0
B11: 3 | D11: =+O10 -> 0 | E11: =$S$8*D11/1000 -> 0 | H11: =$S$8*G11/1000 -> 0 | I11: =D11+G11 -> 0 | J11: =$S$8*I11/1000 -> 0 | L11: =K11*S$6/1000 -> 0 | M11: =K11*S$8/1000 -> 0 | N11: =K11*S$7/1000 -> 0 | O11: =I11-K11 -> 0 | P11: =$S$8*O11/1000 -> 0
B12: 4 | D12: =+O11 -> 0 | E12: =$S$8*D12/1000 -> 0 | H12: =$S$8*G12/1000 -> 0 | I12: =D12+G12 -> 0 | J12: =$S$8*I12/1000 -> 0 | L12: =K12*S$6/1000 -> 0 | M12: =K12*S$8/1000 -> 0 | N12: =K12*S$7/1000 -> 0 | O12: =I12-K12 -> 0 | P12: =$S$8*O12/1000 -> 0
B13: 5 | D13: =+O12 -> 0 | E13: =$S$8*D13/1000 -> 0 | H13: =$S$8*G13/1000 -> 0 | I13: =D13+G13 -> 0 | J13: =$S$8*I13/1000 -> 0 | L13: =K13*S$6/1000 -> 0 | M13: =K13*S$8/1000 -> 0 | N13: =K13*S$7/1000 -> 0 | O13: =I13-K13 -> 0 | P13: =$S$8*O13/1000 -> 0
B14: 6 | D14: =+O13 -> 0 | E14: =$S$8*D14/1000 -> 0 | H14: =$S$8*G14/1000 -> 0 | I14: =D14+G14 -> 0 | J14: =$S$8*I14/1000 -> 0 | L14: =K14*S$6/1000 -> 0 | M14: =K14*S$8/1000 -> 0 | N14: =K14*S$7/1000 -> 0 | O14: =I14-K14 -> 0 | P14: =$S$8*O14/1000 -> 0
B15: 7 | D15: =+O14 -> 0 | E15: =$S$8*D15/1000 -> 0 | H15: =$S$8*G15/1000 -> 0 | I15: =D15+G15 -> 0 | J15: =$S$8*I15/1000 -> 0 | L15: =K15*S$6/1000 -> 0 | M15: =K15*S$8/1000 -> 0 | N15: =K15*S$7/1000 -> 0 | O15: =I15-K15 -> 0 | P15: =$S$8*O15/1000 -> 0
B16: 8 | D16: =+O15 -> 0 | E16: =$S$8*D16/1000 -> 0 | H16: =$S$8*G16/1000 -> 0 | I16: =D16+G16 -> 0 | J16: =$S$8*I16/1000 -> 0 | L16: =K16*S$6/1000 -> 0 | M16: =K16*S$8/1000 -> 0 | N16: =K16*S$7/1000 -> 0 | O16: =I16-K16 -> 0 | P16: =$S$8*O16/1000 -> 0
B17: 9 | D17: =+O16 -> 0 | E17: =$S$8*D17/1000 -> 0 | H17: =$S$8*G17/1000 -> 0 | I17: =D17+G17 -> 0 | J17: =$S$8*I17/1000 -> 0 | L17: =K17*S$6/1000 -> 0 | M17: =K17*S$8/1000 -> 0 | N17: =K17*S$7/1000 -> 0 | O17: =I17-K17 -> 0 | P17: =$S$8*O17/1000 -> 0
B18: 10 | D18: =+O17 -> 0 | E18: =$S$8*D18/1000 -> 0 | H18: =$S$8*G18/1000 -> 0 | I18: =D18+G18 -> 0 | J18: =$S$8*I18/1000 -> 0 | L18: =K18*S$6/1000 -> 0 | M18: =K18*S$8/1000 -> 0 | N18: =K18*S$7/1000 -> 0 | O18: =I18-K18 -> 0 | P18: =$S$8*O18/1000 -> 0
B19: 11 | D19: =+O18 -> 0 | E19: =$S$8*D19/1000 -> 0 | H19: =$S$8*G19/1000 -> 0 | I19: =D19+G19 -> 0 | J19: =$S$8*I19/1000 -> 0 | L19: =K19*S$6/1000 -> 0 | M19: =K19*S$8/1000 -> 0 | N19: =K19*S$7/1000 -> 0 | O19: =I19-K19 -> 0 | P19: =$S$8*O19/1000 -> 0
B20: 12 | D20: =+O19 -> 0 | E20: =$S$8*D20/1000 -> 0 | H20: =$S$8*G20/1000 -> 0 | I20: =D20+G20 -> 0 | J20: =$S$8*I20/1000 -> 0 | L20: =K20*S$6/1000 -> 0 | M20: =K20*S$8/1000 -> 0 | N20: =K20*S$7/1000 -> 0 | O20: =I20-K20 -> 0 | P20: =$S$8*O20/1000 -> 0
B21: 13 | D21: =+O20 -> 0 | E21: =$S$8*D21/1000 -> 0 | H21: =$S$8*G21/1000 -> 0 | I21: =D21+G21 -> 0 | J21: =$S$8*I21/1000 -> 0 | L21: =K21*S$6/1000 -> 0 | M21: =K21*S$8/1000 -> 0 | N21: =K21*S$7/1000 -> 0 | O21: =I21-K21 -> 0 | P21: =$S$8*O21/1000 -> 0
... B28: 20 | D28: =+O27 -> 0 | E28: =$S$8*D28/1000 -> 0 | H28: =$S$8*G28/1000 -> 0 | I28: =D28+G28 -> 0 | J28: =$S$8*I28/1000 -> 0 | L28: =K28*S$6/1000 -> 0 | M28: =K28*S$8/1000 -> 0 | N28: =K28*S$7/1000 -> 0 | O28: =I28-K28 -> 0 | P28: =$S$8*O28/1000 -> 0
B29: 21 | D29: =+O28 -> 0 | E29: =$S$8*D29/1000 -> 0 | H29: =$S$8*G29/1000 -> 0 | I29: =D29+G29 -> 0 | J29: 0.222 | L29: =K29*S$6/1000 -> 0 | M29: =K29*S$8/1000 -> 0 | N29: =K29*S$7/1000 -> 0 | O29: =I29-K29 -> 0 | P29: =$S$8*O29/1000 -> 0
B30: 22 | D30: =+O29 -> 0 | E30: =$S$8*D30/1000 -> 0 | H30: =$S$8*G30/1000 -> 0 | I30: =D30+G30 -> 0 | J30: =$S$8*I30/1000 -> 0 | L30: =K30*S$6/1000 -> 0 | M30: =K30*S$8/1000 -> 0 | N30: =K30*S$7/1000 -> 0 | O30: =I30-K30 -> 0 | P30: =$S$8*O30/1000 -> 0
B31: 23 | D31: =+O30 -> 0 | E31: =$S$8*D31/1000 -> 0 | H31: =$S$8*G31/1000 -> 0 | I31: =D31+G31 -> 0 | J31: =$S$8*I31/1000 -> 0 | L31: =K31*S$6/1000 -> 0 | M31: =K31*S$8/1000 -> 0 | N31: =K31*S$7/1000 -> 0 | O31: =I31-K31 -> 0 | P31: =$S$8*O31/1000 -> 0
B32: 24 | D32: =+O31 -> 0 | E32: =$S$8*D32/1000 -> 0 | H32: =$S$8*G32/1000 -> 0 | I32: =D32+G32 -> 0 | J32: =$S$8*I32/1000 -> 0 | L32: =K32*S$6/1000 -> 0 | M32: =K32*S$8/1000 -> 0 | N32: =K32*S$7/1000 -> 0 | O32: =I32-K32 -> 0 | P32: =$S$8*O32/1000 -> 0
B33: 25 | D33: =+O32 -> 0 | E33: =$S$8*D33/1000 -> 0 | H33: =$S$8*G33/1000 -> 0 | I33: =D33+G33 -> 0 | J33: =$S$8*I33/1000 -> 0 | L33: =K33*S$6/1000 -> 0 | M33: =K33*S$8/1000 -> 0 | N33: =K33*S$7/1000 -> 0 | O33: =I33-K33 -> 0 | P33: =$S$8*O33/1000 -> 0
B34: 26 | D34: =+O33 -> 0 | E34: =$S$8*D34/1000 -> 0 | H34: =$S$8*G34/1000 -> 0 | I34: =D34+G34 -> 0 | J34: =$S$8*I34/1000 -> 0 | L34: =K34*S$6/1000 -> 0 | M34: =K34*S$8/1000 -> 0 | N34: =K34*S$7/1000 -> 0 | O34: =I34-K34 -> 0 | P34: =$S$8*O34/1000 -> 0
B35: 27 | D35: =+O34 -> 0 | E35: =$S$8*D35/1000 -> 0 | H35: =$S$8*G35/1000 -> 0 | I35: =D35+G35 -> 0 | J35: =$S$8*I35/1000 -> 0 | L35: =K35*S$6/1000 -> 0 | M35: =K35*S$8/1000 -> 0 | N35: =K35*S$7/1000 -> 0 | O35: =I35-K35 -> 0 | P35: =$S$8*O35/1000 -> 0
B36: 28 | D36: =+O35 -> 0 | E36: =$S$8*D36/1000 -> 0 | H36: =$S$8*G36/1000 -> 0 | I36: =D36+G36 -> 0 | J36: =$S$8*I36/1000 -> 0 | L36: =K36*S$6/1000 -> 0 | M36: =K36*S$8/1000 -> 0 | N36: =K36*S$7/1000 -> 0 | O36: =I36-K36 -> 0 | P36: =$S$8*O36/1000 -> 0
B37: 29 | D37: =+O36 -> 0 | E37: =$S$8*D37/1000 -> 0 | H37: =$S$8*G37/1000 -> 0 | I37: =D37+G37 -> 0 | J37: =$S$8*I37/1000 -> 0 | L37: =K37*S$6/1000 -> 0 | M37: =K37*S$8/1000 -> 0 | N37: =K37*S$7/1000 -> 0 | O37: =I37-K37 -> 0 | P37: =$S$8*O37/1000 -> 0
B38: 30 | D38: =+O37 -> 0 | E38: =$S$8*D38/1000 -> 0 | H38: =$S$8*G38/1000 -> 0 | I38: =D38+G38 -> 0 | J38: =$S$8*I38/1000 -> 0 | L38: =K38*S$6/1000 -> 0 | M38: =K38*S$8/1000 -> 0 | N38: =K38*S$7/1000 -> 0 | O38: =I38-K38 -> 0 | P38: =$S$8*O38/1000 -> 0
B39: 31 | D39: =+O38 -> 0 | E39: =$S$8*D39/1000 -> 0 | H39: =$S$8*G39/1000 -> 0 | I39: =D39+G39 -> 0 | J39: =$S$8*I39/1000 -> 0 | L39: =K39*S$6/1000 -> 0 | M39: =K39*S$8/1000 -> 0 | N39: =K39*S$7/1000 -> 0 | O39: =I39-K39 -> 0 | P39: =$S$8*O39/1000 -> 0
B40: TOTAL | F40: =SUM(F9:F39) -> 0 | G40: =SUM(G9:G39) -> 0 | H40: =SUM(H9:H39) -> 0 | K40: =SUM(K9:K39) -> 0 | L40: =SUM(L9:L39) -> 0 | N40: =SUM(N9:N39) -> 0
B42: PACK SHEET | G42: =G40*S7/1000 -> 0 | H42: =+G40*S6/1000 -> 0 | J42: DESPATCH PACKSHEET | L42: =K40*S7/1000 -> 0

Sheet 40-4.5-OZ
B2: STOCK CARD- REF.NO
B3: THE EMPIRE JUTE MILL | R3: HESSIAN
B4: HESSIAN CLOTH 40-4.5-OZ | R4: SACKING
A5: NATURE OF PACKING :- 1/B 2000 YDS | R5: YARN
B6: DATE | D6: OPENING BALANCE | G6: RECEIPT | I6: TOTAL | K6: ISSUES | M6: GROSS WT | O6: CLOSING BALLACE | Q6: REMARKS | R6: NET WGT. PER BALE | S6: 255.15
D7: NO.OF | E7: WEIGHT IN | G7: NO.OF | H7: WEIGHT IN | I7: NO.OF | J7: WEIGHT IN | K7: NO.OF | L7: NET WT | O7: NO.OF | P7: WEIGHT IN | R7: P.SHEET WGT | S7: =S6*0.75% -> 1.913625
D8: BALE | E8: KGS | G8: BALE | H8: KGS | I8: BALE | J8: KGS | K8: BALE | L8: KGS | N8: PACK SHEET | O8: BALE | P8: KGS | R8: TOTAL WGT | S8: =S6+S7 -> 257.06363
B9: 1 | E9: =$S$8*D9/1000 -> 0 | H9: =$S$8*G9/1000 -> 0 | I9: =D9+G9 -> 0 | J9: =$S$8*I9/1000 -> 0 | L9: =K9*S$6/1000 -> 0 | M9: =K9*S$8/1000 -> 0 | N9: =K9*S$7/1000 -> 0 | O9: =I9-K9 -> 0 | P9: =$S$8*O9/1000 -> 0
B10: 2 | D10: =+O9 -> 0 | E10: =$S$8*D10/1000 -> 0 | H10: =$S$8*G10/1000 -> 0 | I10: =D10+G10 -> 0 | J10: =$S$8*I10/1000 -> 0 | L10: =K10*S$6/1000 -> 0 | M10: =K10*S$8/1000 -> 0 | N10: =K10*S$7/1000 -> 0 | O10: =I10-K10 -> 0 | P10: =$S$8*O10/1000 -> 0
B11: 3 | D11: =+O10 -> 0 | E11: =$S$8*D11/1000 -> 0 | H11: =$S$8*G11/1000 -> 0 | I11: =D11+G11 -> 0 | J11: =$S$8*I11/1000 -> 0 | L11: =K11*S$6/1000 -> 0 | M11: =K11*S$8/1000 -> 0 | N11: =K11*S$7/1000 -> 0 | O11: =I11-K11 -> 0 | P11: =$S$8*O11/1000 -> 0
B12: 4 | D12: =+O11 -> 0 | E12: =$S$8*D12/1000 -> 0 | H12: =$S$8*G12/1000 -> 0 | I12: =D12+G12 -> 0 | J12: =$S$8*I12/1000 -> 0 | L12: =K12*S$6/1000 -> 0 | M12: =K12*S$8/1000 -> 0 | N12: =K12*S$7/1000 -> 0 | O12: =I12-K12 -> 0 | P12: =$S$8*O12/1000 -> 0
B13: 5 | D13: =+O12 -> 0 | E13: =$S$8*D13/1000 -> 0 | H13: =$S$8*G13/1000 -> 0 | I13: =D13+G13 -> 0 | J13: =$S$8*I13/1000 -> 0 | L13: =K13*S$6/1000 -> 0 | M13: =K13*S$8/1000 -> 0 | N13: =K13*S$7/1000 -> 0 | O13: =I13-K13 -> 0 | P13: =$S$8*O13/1000 -> 0
B14: 6 | D14: =+O13 -> 0 | E14: =$S$8*D14/1000 -> 0 | H14: =$S$8*G14/1000 -> 0 | I14: =D14+G14 -> 0 | J14: =$S$8*I14/1000 -> 0 | L14: =K14*S$6/1000 -> 0 | M14: =K14*S$8/1000 -> 0 | N14: =K14*S$7/1000 -> 0 | O14: =I14-K14 -> 0 | P14: =$S$8*O14/1000 -> 0
B15: 7 | D15: =+O14 -> 0 | E15: =$S$8*D15/1000 -> 0 | H15: =$S$8*G15/1000 -> 0 | I15: =D15+G15 -> 0 | J15: =$S$8*I15/1000 -> 0 | L15: =K15*S$6/1000 -> 0 | M15: =K15*S$8/1000 -> 0 | N15: =K15*S$7/1000 -> 0 | O15: =I15-K15 -> 0 | P15: =$S$8*O15/1000 -> 0
B16: 8 | D16: =+O15 -> 0 | E16: =$S$8*D16/1000 -> 0 | H16: =$S$8*G16/1000 -> 0 | I16: =D16+G16 -> 0 | J16: =$S$8*I16/1000 -> 0 | L16: =K16*S$6/1000 -> 0 | M16: =K16*S$8/1000 -> 0 | N16: =K16*S$7/1000 -> 0 | O16: =I16-K16 -> 0 | P16: =$S$8*O16/1000 -> 0
B17: 9 | D17: =+O16 -> 0 | E17: =$S$8*D17/1000 -> 0 | H17: =$S$8*G17/1000 -> 0 | I17: =D17+G17 -> 0 | J17: =$S$8*I17/1000 -> 0 | L17: =K17*S$6/1000 -> 0 | M17: =K17*S$8/1000 -> 0 | N17: =K17*S$7/1000 -> 0 | O17: =I17-K17 -> 0 | P17: =$S$8*O17/1000 -> 0
B18: 10 | D18: =+O17 -> 0 | E18: =$S$8*D18/1000 -> 0 | H18: =$S$8*G18/1000 -> 0 | I18: =D18+G18 -> 0 | J18: =$S$8*I18/1000 -> 0 | L18: =K18*S$6/1000 -> 0 | M18: =K18*S$8/1000 -> 0 | N18: =K18*S$7/1000 -> 0 | O18: =I18-K18 -> 0 | P18: =$S$8*O18/1000 -> 0
B19: 11 | D19: =+O18 -> 0 | E19: =$S$8*D19/1000 -> 0 | H19: =$S$8*G19/1000 -> 0 | I19: =D19+G19 -> 0 | J19: =$S$8*I19/1000 -> 0 | L19: =K19*S$6/1000 -> 0 | M19: =K19*S$8/1000 -> 0 | N19: =K19*S$7/1000 -> 0 | O19: =I19-K19 -> 0 | P19: =$S$8*O19/1000 -> 0
B20: 12 | D20: =+O19 -> 0 | E20: =$S$8*D20/1000 -> 0 | H20: =$S$8*G20/1000 -> 0 | I20: =D20+G20 -> 0 | J20: =$S$8*I20/1000 -> 0 | L20: =K20*S$6/1000 -> 0 | M20: =K20*S$8/1000 -> 0 | N20: =K20*S$7/1000 -> 0 | O20: =I20-K20 -> 0 | P20: =$S$8*O20/1000 -> 0
B21: 13 | D21: =+O20 -> 0 | E21: =$S$8*D21/1000 -> 0 | H21: =$S$8*G21/1000 -> 0 | I21: =D21+G21 -> 0 | J21: =$S$8*I21/1000 -> 0 | L21: =K21*S$6/1000 -> 0 | M21: =K21*S$8/1000 -> 0 | N21: =K21*S$7/1000 -> 0 | O21: =I21-K21 -> 0 | P21: =$S$8*O21/1000 -> 0
... B39: 31 | D39: =+O38 -> 0 | E39: =$S$8*D39/1000 -> 0 | H39: =$S$8*G39/1000 -> 0 | I39: =D39+G39 -> 0 | J39: =$S$8*I39/1000 -> 0 | L39: =K39*S$6/1000 -> 0 | M39: =K39*S$8/1000 -> 0 | N39: =K39*S$7/1000 -> 0 | O39: =I39-K39 -> 0 | P39: =$S$8*O39/1000 -> 0
B40: TOTAL | F40: =SUM(F9:F39) -> 0 | G40: =SUM(G9:G39) -> 0 | H40: =SUM(H9:H39) -> 0 | K40: =SUM(K9:K39) -> 0 | L40: =SUM(L9:L39) -> 0 | N40: =SUM(N9:N39) -> 0
B42: PACK SHEET | G42: =G40*S7/1000 -> 0 | H42: =+G40*S6/1000 -> 0 | J42: DESPATCH PACKSHEET | L42: =K40*S7/1000 -> 0

Sheet 36-4.05 OZ
B2: STOCK CARD- REF.NO
B3: THE EMPIRE JUTE MILL | R3: HESSIAN
B4: DESCRIPTION OF GOODS:- H.CLOTH 36-4.05 OZ | R4: SACKING
A5: NATURE OF PACKING :- 1/B 1828.80 MTR | R5: YARN
B6: DATE | D6: OPENING BALANCE | G6: RECEIPT | I6: TOTAL | K6: ISSUES | M6: GROSS WT | O6: CLOSING BALLACE | Q6: REMARKS | R6: NET WGT. PER BALE | S6: 229.63
D7: NO.OF | E7: WEIGHT IN | G7: NO.OF | H7: WEIGHT IN | I7: NO.OF | J7: WEIGHT IN | K7: NO.OF | L7: NET WT | O7: NO.OF | P7: WEIGHT IN | R7: P.SHEET WGT | S7: =S6*0.75% -> 1.722225
D8: BALE | E8: KGS | G8: BALE | H8: KGS | I8: BALE | J8: KGS | K8: BALE | L8: KGS | N8: PACK SHEET | O8: BALE | P8: KGS | R8: TOTAL WGT | S8: =S6+S7 -> 231.35223
B9: 1 | E9: =$S$8*D9/1000 -> 0 | H9: =$S$8*G9/1000 -> 0 | I9: =D9+G9 -> 0 | J9: =$S$8*I9/1000 -> 0 | L9: =K9*S$8/1000 -> 0 | M9: =+K9*S$8/1000 -> 0 | N9: =K9*S$7/1000 -> 0 | O9: =D9+G9-K9 -> 0 | P9: =$S$8*O9/1000 -> 0 | Q9: =P9*T8/1000 -> 0
B10: 2 | E10: =$S$8*D10/1000 -> 0 | H10: =$S$8*G10/1000 -> 0 | I10: =D10+G10 -> 0 | J10: =$S$8*I10/1000 -> 0 | L10: =K10*S$8/1000 -> 0 | M10: =+K10*S$8/1000 -> 0 | N10: =K10*S$7/1000 -> 0 | O10: =D10+G10-K10 -> 0 | P10: =$S$8*O10/1000 -> 0
B11: 3 | D11: =+O10 -> 0 | E11: =$S$8*D11/1000 -> 0 | H11: =$S$8*G11/1000 -> 0 | I11: =D11+G11 -> 0 | J11: =$S$8*I11/1000 -> 0 | L11: =K11*S$8/1000 -> 0 | M11: =+K11*S$8/1000 -> 0 | N11: =K11*S$7/1000 -> 0 | O11: =D11+G11-K11 -> 0 | P11: =$S$8*O11/1000 -> 0
B12: 4 | D12: =+O11 -> 0 | E12: =$S$8*D12/1000 -> 0 | H12: =$S$8*G12/1000 -> 0 | I12: =D12+G12 -> 0 | J12: =$S$8*I12/1000 -> 0 | L12: =K12*S$6/1000 -> 0 | M12: =+K12*S$8/1000 -> 0 | N12: =K12*S$7/1000 -> 0 | O12: =D12+G12-K12 -> 0 | P12: =$S$8*O12/1000 -> 0
B13: 5 | D13: =+O12 -> 0 | E13: =$S$8*D13/1000 -> 0 | H13: =$S$8*G13/1000 -> 0 | I13: =D13+G13 -> 0 | J13: =$S$8*I13/1000 -> 0 | L13: =K13*S$6/1000 -> 0 | M13: =+K13*S$8/1000 -> 0 | N13: =K13*S$7/1000 -> 0 | O13: =D13+G13-K13 -> 0 | P13: =$S$8*O13/1000 -> 0
B14: 6 | D14: =+O13 -> 0 | E14: =$S$8*D14/1000 -> 0 | H14: =$S$8*G14/1000 -> 0 | I14: =D14+G14 -> 0 | J14: =$S$8*I14/1000 -> 0 | L14: =K14*S$6/1000 -> 0 | M14: =+K14*S$8/1000 -> 0 | N14: =K14*S$7/1000 -> 0 | O14: =D14+G14-K14 -> 0 | P14: =$S$8*O14/1000 -> 0
B15: 7 | D15: =+O14 -> 0 | E15: =$S$8*D15/1000 -> 0 | H15: =$S$8*G15/1000 -> 0 | I15: =D15+G15 -> 0 | J15: =$S$8*I15/1000 -> 0 | L15: =K15*S$6/1000 -> 0 | M15: =+K15*S$8/1000 -> 0 | N15: =K15*S$7/1000 -> 0 | O15: =D15+G15-K15 -> 0 | P15: =$S$8*O15/1000 -> 0
B16: 8 | D16: =+O15 -> 0 | E16: =$S$8*D16/1000 -> 0 | H16: =$S$8*G16/1000 -> 0 | I16: =D16+G16 -> 0 | J16: =$S$8*I16/1000 -> 0 | L16: =K16*S$6/1000 -> 0 | M16: =+K16*S$8/1000 -> 0 | N16: =K16*S$7/1000 -> 0 | O16: =D16+G16-K16 -> 0 | P16: =$S$8*O16/1000 -> 0
B17: 9 | D17: =+D16 -> 0 | E17: =$S$8*D17/1000 -> 0 | H17: =$S$8*G17/1000 -> 0 | I17: =D17+G17 -> 0 | J17: =$S$8*I17/1000 -> 0 | L17: =K17*S$6/1000 -> 0 | M17: =+K17*S$8/1000 -> 0 | N17: =K17*S$7/1000 -> 0 | O17: =D17+G17-K17 -> 0 | P17: =$S$8*O17/1000 -> 0
B18: 10 | D18: =+D17 -> 0 | E18: =$S$8*D18/1000 -> 0 | H18: =$S$8*G18/1000 -> 0 | I18: =D18+G18 -> 0 | J18: =$S$8*I18/1000 -> 0 | L18: =K18*S$6/1000 -> 0 | M18: =+K18*S$8/1000 -> 0 | N18: =K18*S$7/1000 -> 0 | O18: =D18+G18-K18 -> 0 | P18: =$S$8*O18/1000 -> 0
B19: 11 | D19: =+D18 -> 0 | E19: =$S$8*D19/1000 -> 0 | H19: =$S$8*G19/1000 -> 0 | I19: =D19+G19 -> 0 | J19: =$S$8*I19/1000 -> 0 | L19: =K19*S$6/1000 -> 0 | M19: =+K19*S$8/1000 -> 0 | N19: =K19*S$7/1000 -> 0 | O19: =D19+G19-K19 -> 0 | P19: =$S$8*O19/1000 -> 0
B20: 12 | D20: =+D19 -> 0 | E20: =$S$8*D20/1000 -> 0 | H20: =$S$8*G20/1000 -> 0 | I20: =D20+G20 -> 0 | J20: =$S$8*I20/1000 -> 0 | L20: =K20*S$6/1000 -> 0 | M20: =+K20*S$8/1000 -> 0 | N20: =K20*S$7/1000 -> 0 | O20: =D20+G20-K20 -> 0 | P20: =$S$8*O20/1000 -> 0
B21: 13 | D21: =+D20 -> 0 | E21: =$S$8*D21/1000 -> 0 | H21: =$S$8*G21/1000 -> 0 | I21: =D21+G21 -> 0 | J21: =$S$8*I21/1000 -> 0 | L21: =K21*S$6/1000 -> 0 | M21: =+K21*S$8/1000 -> 0 | N21: =K21*S$7/1000 -> 0 | O21: =D21+G21-K21 -> 0 | P21: =$S$8*O21/1000 -> 0
B22: 14 | D22: =+D21 -> 0 | E22: =$S$8*D22/1000 -> 0 | H22: =$S$8*G22/1000 -> 0 | I22: =D22+G22 -> 0 | J22: =$S$8*I22/1000 -> 0 | L22: =K22*S$6/1000 -> 0 | M22: =+K22*S$8/1000 -> 0 | N22: =K22*S$7/1000 -> 0 | O22: =D22+G22-K22 -> 0 | P22: =$S$8*O22/1000 -> 0
B23: 15 | D23: =+D22 -> 0 | E23: =$S$8*D23/1000 -> 0 | H23: =$S$8*G23/1000 -> 0 | I23: =D23+G23 -> 0 | J23: =$S$8*I23/1000 -> 0 | L23: =K23*S$6/1000 -> 0 | M23: =+K23*S$8/1000 -> 0 | N23: =K23*S$7/1000 -> 0 | O23: =D23+G23-K23 -> 0 | P23: =$S$8*O23/1000 -> 0
B24: 16 | D24: =+D23 -> 0 | E24: =$S$8*D24/1000 -> 0 | H24: =$S$8*G24/1000 -> 0 | I24: =D24+G24 -> 0 | J24: =$S$8*I24/1000 -> 0 | L24: =K24*S$6/1000 -> 0 | M24: =+K24*S$8/1000 -> 0 | N24: =K24*S$7/1000 -> 0 | O24: =D24+G24-K24 -> 0 | P24: =$S$8*O24/1000 -> 0
B25: 17 | D25: =+D24 -> 0 | E25: =$S$8*D25/1000 -> 0 | H25: =$S$8*G25/1000 -> 0 | I25: =D25+G25 -> 0 | J25: =$S$8*I25/1000 -> 0 | L25: =K25*S$6/1000 -> 0 | M25: =+K25*S$8/1000 -> 0 | N25: =K25*S$7/1000 -> 0 | O25: =D25+G25-K25 -> 0 | P25: =$S$8*O25/1000 -> 0
B26: 18 | D26: =+D25 -> 0 | E26: =$S$8*D26/1000 -> 0 | H26: =$S$8*G26/1000 -> 0 | I26: =D26+G26 -> 0 | J26: =$S$8*I26/1000 -> 0 | L26: =K26*S$6/1000 -> 0 | M26: =+K26*S$8/1000 -> 0 | N26: =K26*S$7/1000 -> 0 | O26: =D26+G26-K26 -> 0 | P26: =$S$8*O26/1000 -> 0
B27: 19 | D27: =+D26 -> 0 | E27: =$S$8*D27/1000 -> 0 | H27: =$S$8*G27/1000 -> 0 | I27: =D27+G27 -> 0 | J27: =$S$8*I27/1000 -> 0 | L27: =K27*S$6/1000 -> 0 | M27: =+K27*S$8/1000 -> 0 | N27: =K27*S$7/1000 -> 0 | O27: =D27+G27-K27 -> 0 | P27: =$S$8*O27/1000 -> 0
B28: 20 | D28: =+D27 -> 0 | E28: =$S$8*D28/1000 -> 0 | H28: =$S$8*G28/1000 -> 0 | I28: =D28+G28 -> 0 | J28: =$S$8*I28/1000 -> 0 | L28: =K28*S$6/1000 -> 0 | M28: =+K28*S$8/1000 -> 0 | N28: =K28*S$7/1000 -> 0 | O28: =D28+G28-K28 -> 0 | P28: =$S$8*O28/1000 -> 0
... B39: 31 | D39: =+D38 -> 0 | E39: =$S$8*D39/1000 -> 0 | H39: =$S$8*G39/1000 -> 0 | I39: =D39+G39 -> 0 | J39: =$S$8*I39/1000 -> 0 | L39: =K39*S$6/1000 -> 0 | M39: =+K39*S$8/1000 -> 0 | N39: =K39*S$7/1000 -> 0 | O39: =D39+G39-K39 -> 0 | P39: =$S$8*O39/1000 -> 0
B40: TOTAL | F40: =SUM(F9:F39) -> 0 | G40: =SUM(G9:G39) -> 0 | H40: =SUM(H9:H39) -> 0 | K40: =SUM(K9:K39) -> 0 | L40: =SUM(L9:L39) -> 0 | M40: =SUM(M9:M39) -> 0 | N40: =SUM(N9:N39) -> 0 | R40: 40 | S40: 6.5 | U40: 40 | V40: 28.35 | X40: 2000
U41: =R40*S40/U40*V40*X40/1000 -> 368.55
B42: PACK SHEET | G42: =G40*S7/1000 -> 0 | H42: =+G40*S6/1000 -> 0 | J42: DESPATCH PACKSHEET | L42: =K40*S7/1000 -> 0 | S42: 0.75 | U42: =U41*S42% -> 2.764125
U43: =U41+U42 -> 371.31412

Sheet 34-9.82
B2: STOCK CARD- REF.NO
B3: THE EMPIRE JUTE MILL | R3: HESSIAN
B4: DESCRIPTION OF GOODS:- CANVASE 34-9.82 | R4: SACKING
A5: NATURE OF PACKING :- 1/B -1500 YDS | R5: YARN
B6: DATE | D6: OPENING BALANCE | G6: RECEIPT | I6: TOTAL | K6: ISSUES | M6: GROSS WT | O6: CLOSING BALLACE | Q6: REMARKS | R6: NET WGT. PER BALE | S6: 417.595
D7: NO.OF | E7: WEIGHT IN | G7: NO.OF | H7: WEIGHT IN | I7: NO.OF | J7: WEIGHT IN | K7: NO.OF | L7: NET WT | O7: NO.OF | P7: WEIGHT IN | R7: P.SHEET WGT | S7: 3.132
D8: BALE | E8: KGS | G8: BALE | H8: KGS | I8: BALE | J8: KGS | K8: BALE | L8: KGS | N8: PACK SHEET | O8: BALE | P8: KGS | R8: TOTAL WGT | S8: =S6+S7 -> 420.727
B9: 1 | E9: =$S$8*D9/1000 -> 0 | H9: =$S$8*G9/1000 -> 0 | I9: =D9+G9 -> 0 | J9: =$S$8*I9/1000 -> 0 | L9: =K9*S$6/1000 -> 0 | M9: =+K9*S$8/1000 -> 0 | N9: =K9*S$7/1000 -> 0 | O9: =D9+G9-K9 -> 0 | P9: =$S$8*O9/1000 -> 0 | Q9: =P9*T8/1000 -> 0
B10: 2 | D10: =+O9 -> 0 | E10: =$S$8*D10/1000 -> 0 | H10: =$S$8*G10/1000 -> 0 | I10: =D10+G10 -> 0 | J10: =$S$8*I10/1000 -> 0 | L10: =K10*S$8/1000 -> 0 | M10: =+K10*S$8/1000 -> 0 | N10: =K10*S$7/1000 -> 0 | O10: =D10+G10-K10 -> 0 | P10: =$S$8*O10/1000 -> 0
B11: 3 | D11: =+O10 -> 0 | E11: =$S$8*D11/1000 -> 0 | H11: =$S$8*G11/1000 -> 0 | I11: =D11+G11 -> 0 | J11: =$S$8*I11/1000 -> 0 | L11: =K11*S$6/1000 -> 0 | M11: =+K11*S$8/1000 -> 0 | N11: =K11*S$7/1000 -> 0 | O11: =D11+G11-K11 -> 0 | P11: =$S$8*O11/1000 -> 0
B12: 4 | D12: =+O11 -> 0 | E12: =$S$8*D12/1000 -> 0 | H12: =$S$8*G12/1000 -> 0 | I12: =D12+G12 -> 0 | J12: =$S$8*I12/1000 -> 0 | L12: =K12*S$6/1000 -> 0 | M12: =+K12*S$8/1000 -> 0 | N12: =K12*S$7/1000 -> 0 | O12: =D12+G12-K12 -> 0 | P12: =$S$8*O12/1000 -> 0
B13: 5 | D13: =+O12 -> 0 | E13: =$S$8*D13/1000 -> 0 | H13: =$S$8*G13/1000 -> 0 | I13: =D13+G13 -> 0 | J13: =$S$8*I13/1000 -> 0 | L13: =K13*S$6/1000 -> 0 | M13: =+K13*S$8/1000 -> 0 | N13: =K13*S$7/1000 -> 0 | O13: =D13+G13-K13 -> 0 | P13: =$S$8*O13/1000 -> 0
B14: 6 | D14: =+O13 -> 0 | E14: =$S$8*D14/1000 -> 0 | H14: =$S$8*G14/1000 -> 0 | I14: =D14+G14 -> 0 | J14: =$S$8*I14/1000 -> 0 | L14: =K14*S$6/1000 -> 0 | M14: =+K14*S$8/1000 -> 0 | N14: =K14*S$7/1000 -> 0 | O14: =D14+G14-K14 -> 0 | P14: =$S$8*O14/1000 -> 0
B15: 7 | D15: =+O14 -> 0 | E15: =$S$8*D15/1000 -> 0 | H15: =$S$8*G15/1000 -> 0 | I15: =D15+G15 -> 0 | J15: =$S$8*I15/1000 -> 0 | L15: =K15*S$6/1000 -> 0 | M15: =+K15*S$8/1000 -> 0 | N15: =K15*S$7/1000 -> 0 | O15: =D15+G15-K15 -> 0 | P15: =$S$8*O15/1000 -> 0
B16: 8 | D16: =+O15 -> 0 | E16: =$S$8*D16/1000 -> 0 | H16: =$S$8*G16/1000 -> 0 | I16: =D16+G16 -> 0 | J16: =$S$8*I16/1000 -> 0 | L16: =K16*S$6/1000 -> 0 | M16: =+K16*S$8/1000 -> 0 | N16: =K16*S$7/1000 -> 0 | O16: =D16+G16-K16 -> 0 | P16: =$S$8*O16/1000 -> 0 | S16: OCT
B17: 9 | D17: =+O16 -> 0 | E17: =$S$8*D17/1000 -> 0 | H17: =$S$8*G17/1000 -> 0 | I17: =D17+G17 -> 0 | J17: =$S$8*I17/1000 -> 0 | L17: =K17*S$6/1000 -> 0 | M17: =+K17*S$8/1000 -> 0 | N17: =K17*S$7/1000 -> 0 | O17: =D17+G17-K17 -> 0 | P17: =$S$8*O17/1000 -> 0
B18: 10 | D18: =+O17 -> 0 | E18: =$S$8*D18/1000 -> 0 | H18: =$S$8*G18/1000 -> 0 | I18: =D18+G18 -> 0 | J18: =$S$8*I18/1000 -> 0 | L18: =K18*S$6/1000 -> 0 | M18: =+K18*S$8/1000 -> 0 | N18: =K18*S$7/1000 -> 0 | O18: =D18+G18-K18 -> 0 | P18: =$S$8*O18/1000 -> 0
B19: 11 | D19: =+O18 -> 0 | E19: =$S$8*D19/1000 -> 0 | H19: =$S$8*G19/1000 -> 0 | I19: =D19+G19 -> 0 | J19: =$S$8*I19/1000 -> 0 | L19: =K19*S$6/1000 -> 0 | M19: =+K19*S$8/1000 -> 0 | N19: =K19*S$7/1000 -> 0 | O19: =D19+G19-K19 -> 0 | P19: =$S$8*O19/1000 -> 0
B20: 12 | D20: =+O19 -> 0 | E20: =$S$8*D20/1000 -> 0 | H20: =$S$8*G20/1000 -> 0 | I20: =D20+G20 -> 0 | J20: =$S$8*I20/1000 -> 0 | L20: =K20*S$6/1000 -> 0 | M20: =+K20*S$8/1000 -> 0 | N20: =K20*S$7/1000 -> 0 | O20: =D20+G20-K20 -> 0 | P20: =$S$8*O20/1000 -> 0
B21: 13 | D21: =+O20 -> 0 | E21: =$S$8*D21/1000 -> 0 | H21: =$S$8*G21/1000 -> 0 | I21: =D21+G21 -> 0 | J21: =$S$8*I21/1000 -> 0 | L21: =K21*S$6/1000 -> 0 | M21: =+K21*S$8/1000 -> 0 | N21: =K21*S$7/1000 -> 0 | O21: =D21+G21-K21 -> 0 | P21: =$S$8*O21/1000 -> 0
B22: 14 | D22: =+O21 -> 0 | E22: =$S$8*D22/1000 -> 0 | H22: =$S$8*G22/1000 -> 0 | I22: =D22+G22 -> 0 | J22: =$S$8*I22/1000 -> 0 | L22: =K22*S$6/1000 -> 0 | M22: =+K22*S$8/1000 -> 0 | N22: =K22*S$7/1000 -> 0 | O22: =D22+G22-K22 -> 0 | P22: =$S$8*O22/1000 -> 0
B23: 15 | D23: =+O22 -> 0 | E23: =$S$8*D23/1000 -> 0 | H23: =$S$8*G23/1000 -> 0 | I23: =D23+G23 -> 0 | J23: =$S$8*I23/1000 -> 0 | L23: =K23*S$6/1000 -> 0 | M23: =+K23*S$8/1000 -> 0 | N23: =K23*S$7/1000 -> 0 | O23: =D23+G23-K23 -> 0 | P23: =$S$8*O23/1000 -> 0
B24: 16 | D24: =+O23 -> 0 | E24: =$S$8*D24/1000 -> 0 | H24: =$S$8*G24/1000 -> 0 | I24: =D24+G24 -> 0 | J24: =$S$8*I24/1000 -> 0 | L24: =K24*S$6/1000 -> 0 | M24: =+K24*S$8/1000 -> 0 | N24: =K24*S$7/1000 -> 0 | O24: =D24+G24-K24 -> 0 | P24: =$S$8*O24/1000 -> 0
B25: 17 | D25: =+O24 -> 0 | E25: =$S$8*D25/1000 -> 0 | H25: =$S$8*G25/1000 -> 0 | I25: =D25+G25 -> 0 | J25: =$S$8*I25/1000 -> 0 | L25: =K25*S$6/1000 -> 0 | M25: =+K25*S$8/1000 -> 0 | N25: =K25*S$7/1000 -> 0 | O25: =D25+G25-K25 -> 0 | P25: =$S$8*O25/1000 -> 0
B26: 18 | D26: =+O25 -> 0 | E26: =$S$8*D26/1000 -> 0 | H26: =$S$8*G26/1000 -> 0 | I26: =D26+G26 -> 0 | J26: =$S$8*I26/1000 -> 0 | L26: =K26*S$6/1000 -> 0 | M26: =+K26*S$8/1000 -> 0 | N26: =K26*S$7/1000 -> 0 | O26: =D26+G26-K26 -> 0 | P26: =$S$8*O26/1000 -> 0
B27: 19 | D27: =+O26 -> 0 | E27: =$S$8*D27/1000 -> 0 | H27: =$S$8*G27/1000 -> 0 | I27: =D27+G27 -> 0 | J27: =$S$8*I27/1000 -> 0 | L27: =K27*S$6/1000 -> 0 | M27: =+K27*S$8/1000 -> 0 | N27: =K27*S$7/1000 -> 0 | O27: =D27+G27-K27 -> 0 | P27: =$S$8*O27/1000 -> 0
B28: 20 | D28: =+O27 -> 0 | E28: =$S$8*D28/1000 -> 0 | H28: =$S$8*G28/1000 -> 0 | I28: =D28+G28 -> 0 | J28: =$S$8*I28/1000 -> 0 | L28: =K28*S$6/1000 -> 0 | M28: =+K28*S$8/1000 -> 0 | N28: =K28*S$7/1000 -> 0 | O28: =D28+G28-K28 -> 0 | P28: =$S$8*O28/1000 -> 0
... B39: 31 | D39: =+O38 -> 0 | E39: =$S$8*D39/1000 -> 0 | H39: =$S$8*G39/1000 -> 0 | I39: =D39+G39 -> 0 | J39: =$S$8*I39/1000 -> 0 | L39: =K39*S$6/1000 -> 0 | M39: =+K39*S$8/1000 -> 0 | N39: =K39*S$7/1000 -> 0 | O39: =D39+G39-K39 -> 0 | P39: =$S$8*O39/1000 -> 0
B40: TOTAL | F40: =SUM(F9:F39) -> 0 | G40: =SUM(G9:G39) -> 0 | H40: =SUM(H9:H39) -> 0 | K40: =SUM(K9:K39) -> 0 | L40: =SUM(L9:L39) -> 0 | M40: =SUM(M9:M39) -> 0 | N40: =SUM(N9:N39) -> 0 | R40: 40 | S40: 6.5 | U40: 40 | V40: 28.35 | X40: 2000
U41: =R40*S40/U40*V40*X40/1000 -> 368.55
B42: PACK SHEET | G42: =G40*S7/1000 -> 0 | H42: =+G40*S6/1000 -> 0 | J42: DESPATCH PACKSHEET | L42: =K40*S7/1000 -> 0 | S42: 0.75 | U42: =U41*S42% -> 2.764125
U43: =U41+U42 -> 371.31412

Sheet 44-5 OZ (2)
B2: STOCK CARD- REF.NO | U2: YRAR | V2: 2023
B3: THE EMPIRE JUTE MILL | R3: HESSIAN
B4: DESCRIPTION OF GOODS:- HESSIAN CLOTH 44-5 OZ | R4: SACKING
A5: NATURE OF PACKING :- 1/B 1000 YDS | R5: YARN
D6: OPENING BALANCE | G6: RECEIPT | I6: TOTAL | K6: ISSUES | M6: GROSS WT | O6: CLOSING BALLACE | Q6: REMARKS | R6: NET WGT. PER BALE | S6: =5.5*28.35*1 -> 155.925 | Y6: 155.925
D7: NO.OF | E7: WEIGHT IN | G7: NO.OF | H7: WEIGHT IN MT | I7: NO.OF | J7: WEIGHT IN | K7: NO.OF | L7: NET WT | O7: NO.OF | P7: WEIGHT IN | R7: P.SHEET WGT | S7: =+S6*0.75% -> 1.1694375 | Y7: =+Y6*2 -> 311.85
B8: DATE | D8: BALE | E8: KGS | G8: BALE | I8: BALE | J8: KGS | K8: BALE | L8: KGS | N8: PACK SHEET | O8: BALE | P8: KGS | R8: TOTAL WGT | S8: =S6+S7 -> 157.09444
B9: 1 | E9: =$S$8*D9/1000 -> 0 | H9: =G9*S$8/1000 -> 0 | I9: =D9+G9 -> 0 | J9: =$S$8*I9/1000 -> 0 | L9: =K9*S$6/1000 -> 0 | M9: =K9*S$8/1000 -> 0 | N9: =K9*S$7/1000 -> 0 | O9: =I9-K9 -> 0 | P9: =$S$8*O9/1000 -> 0
B10: 2 | E10: =$S$8*D10/1000 -> 0 | H10: =G10*S$8/1000 -> 0 | I10: =D10+G10 -> 0 | J10: =$S$8*I10/1000 -> 0 | L10: =K10*S$6/1000 -> 0 | M10: =K10*S$8/1000 -> 0 | N10: =K10*S$7/1000 -> 0 | O10: =I10-K10 -> 0 | P10: =$S$8*O10/1000 -> 0
B11: 3 | E11: =$S$8*D11/1000 -> 0 | H11: =G11*S$8/1000 -> 0 | I11: =D11+G11 -> 0 | J11: =$S$8*I11/1000 -> 0 | L11: =K11*S$6/1000 -> 0 | M11: =K11*S$8/1000 -> 0 | N11: =K11*S$7/1000 -> 0 | O11: =I11-K11 -> 0 | P11: =$S$8*O11/1000 -> 0
B12: 4 | E12: =$S$8*D12/1000 -> 0 | H12: =G12*S$8/1000 -> 0 | I12: =D12+G12 -> 0 | J12: =$S$8*I12/1000 -> 0 | L12: =K12*S$6/1000 -> 0 | M12: =K12*S$8/1000 -> 0 | N12: =K12*S$7/1000 -> 0 | O12: =I12-K12 -> 0 | P12: =$S$8*O12/1000 -> 0
B13: 5 | E13: =$S$8*D13/1000 -> 0 | H13: =G13*S$8/1000 -> 0 | I13: =D13+G13 -> 0 | J13: =$S$8*I13/1000 -> 0 | L13: =K13*S$6/1000 -> 0 | M13: =K13*S$8/1000 -> 0 | N13: =K13*S$7/1000 -> 0 | O13: =I13-K13 -> 0 | P13: =$S$8*O13/1000 -> 0
B14: 6 | E14: =$S$8*D14/1000 -> 0 | H14: =G14*S$8/1000 -> 0 | I14: =D14+G14 -> 0 | J14: =$S$8*I14/1000 -> 0 | L14: =K14*S$6/1000 -> 0 | M14: =K14*S$8/1000 -> 0 | N14: =K14*S$7/1000 -> 0 | O14: =I14-K14 -> 0 | P14: =$S$8*O14/1000 -> 0
B15: 7 | E15: =$S$8*D15/1000 -> 0 | H15: =G15*S$8/1000 -> 0 | I15: =D15+G15 -> 0 | J15: =$S$8*I15/1000 -> 0 | L15: =K15*S$6/1000 -> 0 | M15: =K15*S$8/1000 -> 0 | N15: =K15*S$7/1000 -> 0 | O15: =I15-K15 -> 0 | P15: =$S$8*O15/1000 -> 0 | S15: =5.5*28.35*1 -> 155.925
B16: 8 | E16: =$S$8*D16/1000 -> 0 | H16: =G16*S$8/1000 -> 0 | I16: =D16+G16 -> 0 | J16: =$S$8*I16/1000 -> 0 | L16: =K16*S$6/1000 -> 0 | M16: =K16*S$8/1000 -> 0 | N16: =K16*S$7/1000 -> 0 | O16: =I16-K16 -> 0 | P16: =$S$8*O16/1000 -> 0 | S16: =+S15*0.75% -> 1.1694375
B17: 9 | E17: =$S$8*D17/1000 -> 0 | H17: =G17*S$8/1000 -> 0 | I17: =D17+G17 -> 0 | J17: =$S$8*I17/1000 -> 0 | L17: =K17*S$6/1000 -> 0 | M17: =K17*S$8/1000 -> 0 | N17: =K17*S$7/1000 -> 0 | O17: =I17-K17 -> 0 | P17: =$S$8*O17/1000 -> 0 | S17: =+S15+S16 -> 157.09444
